Workbook

Sheet Leads verificados
A1: ﻿Nombre | B1: Categoría | C1: Direccion | D1: Localidad | E1: Provincia | F1: Website | G1: Teléfono | H1: email | I1: mail verificado
A2: FONTANERÍA ERIKA | B2: Fontanero | C2: Plaza de los Oficios, 1, 04230 Huércal de Almería, Almería | D2: Huércal de Almería | E2: Almería | F2: fontaneriaerika.com | G2: 643 43 06 37 | H2: jlorenzofernandez32@gmail.com | I2: TRUE
A3: ROTRISA S.L.U | B3: Tienda de artículos de fontanería | C3: Ctra. Sierra Alhamilla, 306, 04007 Almería | D3: Almería | E3: Almería | F3: rotrisa.com | G3: 950 22 03 11 | H3: cial@rotrisa.com | I3: TRUE
A4: Rafael López Obstrucciones Y Recalos | B4: Fontanero | C4: Calle Sierra de Castillejo, 11, BAJO, 04240 Viator, Almería | D4: Viator | E4: Almería | F4: rafaellopezfontaneriayreformas.com | G4: 950 14 25 60 | H4: rafaellopez@rlopezm.com | I4: TRUE
A5: SC Hogar Multiservicio | B5: Fontanero | D5: Abla | F5: schogar.com | G5: 638 82 46 15 | H5: servicios@schogar.com | I5: TRUE
A6: FONTACLIMA | B6: Fontanero | C6: Av. Segunda Aguada, 21, 11012 Cádiz | D6: Cádiz | E6: Cádiz | F6: fontaclimacadiz.es | G6: 856 07 36 25 | H6: fontaclima@hotmail.es | I6: TRUE
A7: Fontanería Altamirano | B7: Fontanero | C7: Calle Francisco García de Sola, 10, 11008 Cádiz | D7: Cádiz | E7: Cádiz | F7: fontaneriaaltamirano.es | G7: 956 22 15 87 | H7: altamiranosl@live.com | I7: TRUE
A8: DESATASCOS PA’YÁ | B8: Fontanero | C8: Calle Virgen de las Angustias, 5, 11010 Cádiz | D8: Cádiz | E8: Cádiz | F8: desatascos-paya.ueniweb.com | G8: 655 09 94 85 | H8: jose.m.sanchez.paya@gmail.com | I8: TRUE
A9: Suinprosur SL | B9: Fontanero | C9: Poligono Industrial Salinas de Poniente, c/ Alfred Nobel 22, Nave 2, Módulo B, Buzón 8, 11500 Puerto de Santa María (El), Cádiz | D9: El Puerto de Sta María | E9: Cádiz | F9: suinprosur.es | G9: 956 85 75 96 | H9: suinprosur@suinprosur.es | I9: TRUE
A10: Desatascos Chiclana urgentes 24h | B10: Fontanero | C10: Calle Aurora, 3, 11130 Chiclana de la Frontera, Cádiz | D10: Chiclana de la Frontera | E10: Cádiz | F10: desatascoscurro.es | G10: 650 54 14 92 | H10: desatascosomega@gmail.com | I10: TRUE
A11: Fugascor localizacion de fugas de agua en Córdoba, detección de fugas averías y localizador en Córdoba | B11: Fontanero | C11: Calle Escritora Ana María Matutes, 6, local, 14014 Córdoba | D11: Córdoba | E11: Córdoba | F11: fugascor.com | G11: 661 92 22 32 | H11: fugascor@gmail.com | I11: TRUE
A12: Esmebra | B12: Tienda de artículos de fontanería | C12: Av. de Libia, 71, 14014 Córdoba | D12: Córdoba | E12: Córdoba | F12: esmebra.com | G12: 957 26 10 08 | H12: esmebra@esmebra.com | I12: TRUE
A13: Fontanería Y Gas | B13: Fontanero | D13: Adamuz | F13: fontaneriaygas.com | G13: 667 56 20 77 | H13: fontaneriaygasandalucia@gmail.com | I13: TRUE
A14: SANEAMIENTOS LUQUE, S.L. | B14: Tienda de artículos de fontanería | C14: Calle Infante Molina, 3, 14700 Palma del Río, Córdoba | D14: Palma del Río | E14: Córdoba | F14: saneamientosluque.es | G14: 957 64 33 98 | H14: sanealuque@hotmail.com | I14: TRUE
A15: Canalcor - Canalones En Córdoba | B15: Tienda de artículos de fontanería | C15: Calle la Higuera, 1, 1º 1º, 14720 Almodóvar del Río, Córdoba | D15: Almodóvar del Río | E15: Córdoba | F15: canalcor.com | G15: 610 03 23 91 | H15: canalcor@hotmail.com | I15: TRUE
A16: Julio Saneamientos - Revestimientos | B16: Tienda de artículos de fontanería | C16: Calle Fontanal, 14800 Priego de Córdoba, Córdoba | D16: Priego de Córdoba | E16: Córdoba | F16: revestimientosjulio.es | G16: 957 54 09 43 | H16: revestimiento@revestimientosjulio.es | I16: TRUE
A17: Fontanero en Cordoba | B17: Fontanero | C17: Calle Mateo Inurria, 14001 Córdoba | D17: Córdoba | E17: Córdoba | F17: fontanerocordoba.es | G17: 608 52 40 73 | H17: fontaneroscordoba@gmail.com | I17: TRUE
A18: fontanerogranada.net | B18: Fontanero | D18: Agrón | F18: fontanerogranada.net | G18: 666 58 41 90 | H18: jramonruizcastro@gmail.com | I18: TRUE
A19: Antonio Benítez Torres - Fontanería | B19: Fontanero | C19: Calle Imperio, 32, BAJO, 18007 Granada | D19: Granada | E19: Granada | F19: reformasbenitez.com | G19: 958 12 79 51 | H19: antoniobenitezt@telefonica.net | I19: TRUE
A20: Fontanería Reyes | B20: Fontanero | C20: Calle Laurel, 7, 18195 Cúllar Vega, Granada | D20: Cúllar Vega | E20: Granada | F20: fontaneriareyes.com | G20: 661 84 06 66 | H20: sergioreyesye@gmail.com | I20: TRUE
A21: Desatranques TUBORED Granada | B21: Fontanero | C21: Calle Viñas Viejas, 16, bajo a, 18194 Churriana de la Vega, Granada | D21: Churriana de la Vega | E21: Granada | F21: desatascosgranada.biz | G21: 651 51 03 52 | H21: desatranquessierranevada@gmail.com | I21: TRUE
A22: Suministros Antonio Ruiz | B22: Tienda de artículos de fontanería | C22: N-432, KM. 22, 18230 Atarfe, Granada | D22: Atarfe | E22: Granada | F22: todofontaneria.com | G22: 958 43 90 90 | H22: carlos@todofontaneria.com | I22: TRUE
A23: DESATASCOS GRANADA (FONTADUR) | B23: Fontanero | D23: Agrón | F23: desatascos-granada.es | G23: 677 41 11 40 | H23: instalacionesfontadur@gmail.com | I23: TRUE
A24: Reparaciones y Servicios Dhogar | B24: Fontanero | C24: Calle Casillas de Prats, 16, 18002 Granada | D24: Granada | E24: Granada | F24: reparacionesdhogar.com | G24: 634 61 47 76 | H24: reparaciones@reparacionesdhogar.com | I24: TRUE
A25: DESATASCOS TARTESOS HUELVA | B25: Fontanero | C25: Calle Gonzalo de Berceo, 24, 21005 Huelva | D25: Huelva | E25: Huelva | F25: desatascosenhuelvatartesos.com | G25: 615 54 68 51 | H25: multiserviciostartesos@hotmail.com | I25: TRUE
A26: Fontaneria y Gas Huelva | B26: Fontanero | D26: Alájar | F26: fontaneriaygashuelva.es | G26: 603 45 28 79 | H26: valeocarrasco@gmail.com | I26: TRUE
A27: Fontaneria Prera | B27: Fontanero | C27: Calle Alondra, N 8, 21620 Trigueros, Huelva | D27: Trigueros | E27: Huelva | F27: fontaneria-prera.ueniweb.com | G27: 628 85 02 44 | H27: el090584@hotmail.com | I27: TRUE
A28: Instalaciones Andevalo, S.L.U. | B28: Fontanero | C28: Calle Cuartel, 21560 Paymogo, Huelva | D28: Paymogo | E28: Huelva | F28: instalacionesandevalo.es | G28: 959 57 05 64 | H28: comercio@instalacionesandevalo.es | I28: TRUE
A29: MasFugas localizacion de fugas de agua en Huelva, detección de fugas averías y localizador en Huelva | B29: Fontanero | C29: Calle Menéndez Pelayo, 66, 21730 Almonte, Huelva | D29: Almonte | E29: Huelva | F29: masfugas.es | G29: 635 96 17 57 | H29: masfugas@gmail.com | I29: TRUE
A30: Mulbay Multiservicios | B30: Fontanero | C30: Calle Carlos Cano, 17, 23710 Bailén, Jaén | D30: Bailén | E30: Jaén | F30: mulbay.es | G30: 953 67 01 05 | H30: mulbaymultiservicios@gmail.com | I30: TRUE
A31: Fontanero Autónomo Málaga 649 09 91 90 | B31: Fontanero | C31: Calle, Plaza Arriola, Nº 3, 29005 Málaga | D31: Málaga | E31: Málaga | F31: malagafontanero.es | G31: 649 09 91 90 | H31: malagafont@gmail.com | I31: TRUE
A32: Fontanero en Torremolinos | B32: Fontanero | C32: Av. del Lido, 30, 29620 Torremolinos, Málaga | D32: Torremolinos | E32: Málaga | F32: fontanero-torremolinos.es | G32: 635 15 43 30 | H32: jms@malaga-fontanero.com | I32: TRUE
A33: Sermafugas | B33: Fontanero | C33: Calle Río Sil, n59 Polígono Industrial Trévenez, 29196 Málaga | D33: Málaga | E33: Málaga | F33: sermafugas.com | G33: 690 28 29 96 | H33: sermafugas@gmail.com | I33: TRUE
A34: SUSANFO S.L. Arroyo de la Miel | B34: Tienda de artículos de fontanería | C34: Calle Moscatel, 29, 29631 Benalmádena, Málaga | D34: Benalmádena | E34: Málaga | F34: susanfo.es | G34: 952 44 44 28 | H34: susanfonave@hotmail.com | I34: TRUE
A35: Multiservicios Ceres | B35: Fontanero | C35: Calle Vasija, numero 11, 29591 Maqueda, Málaga | D35: Maqueda | E35: Málaga | F35: multiservicios-ceres.com | G35: 695 87 70 98 | H35: multiserviciosceresmlg@gmail.com | I35: TRUE
A36: Bomdesa | B36: Tienda de artículos de fontanería | C36: La Boheme 14 Pg Alameda, 29006 Málaga | D36: Málaga | E36: Málaga | F36: bomdesa.com | G36: 952 35 20 12 | H36: bomdesa@bomdesa.com | I36: TRUE
A37: Fontanero Málaga Urgente | B37: Fontanero | C37: Calle Acebuche, 34, b3, 29730 Rincón de la Victoria, Málaga | D37: Rincón de la Victoria | E37: Málaga | F37: fontaneromalagaurgente.es | G37: 656 73 74 12 | H37: mundoweb.d@gmail.com | I37: TRUE
A38: Montes Torres Suministros ~ Achedosol Estepona | B38: Tienda de artículos de fontanería | C38: Calle Franklin, 15, 19, 29680 Estepona, Málaga | D38: Estepona | E38: Málaga | F38: montestorres.es | G38: 952 80 46 96 | H38: proyectos@achedosol.es | I38: TRUE
... A43: Repa Instalaciones y Mantenimiento S.L. | B43: Fontanero | C43: Calle María Ortiz, 11 A;BAJO;LOCAL-ACC, 41010 Sevilla | D43: Sevilla | E43: Sevilla | F43: repa.es | G43: 954 33 30 42 | H43: repa@repa.es | I43: TRUE
A44: ROYNOR. Fontanrería - Instalaciones | B44: Fontanero | D44: Aguadulce | F44: roynor.com | G44: 627 43 87 75 | H44: fontaneria@roynor.com | I44: TRUE
...

Sheet centraldecomunicacion.es
A1: ﻿Nombre | B1: Categoría | C1: Direccion | D1: Localidad | E1: Provincia | F1: Website | G1: Teléfono | H1: email | I1: mail verificado
A2: Telegas fontaneria y gas | B2: Fontanero | C2: Av. del Mediterráneo, 95, 04007 Almería | D2: Almería | E2: Almería | G2: 950 15 12 25 | H2: - | I2: =COUNTIF(Estadísticas!I:I,'centraldecomunicacion.es'!H2)>0 -> FALSE
A3: Aquagas Almería S.L. | B3: Fontanero | C3: Calle Juan Lirola, 34, 04004 Almería | D3: Almería | E3: Almería | F3: aquagasalmeria.es | G3: 950 14 15 94 | H3: info@aquagasalmeria.es | I3: =COUNTIF(Estadísticas!I:I,'centraldecomunicacion.es'!H3)>0 -> FALSE
A4: Fontanero en Almería, Fontanería Ignacio González. | B4: Fontanero | C4: Calle Pablo Ruiz Picasso, 20, 04005 Almería | D4: Almería | E4: Almería | F4: fontaneriaignaciogonzalez.es | G4: 950 26 42 35 | H4: info@fontaneriaignaciogonzalez.es | I4: =COUNTIF(Estadísticas!I:I,'centraldecomunicacion.es'!H4)>0 -> FALSE
A5: Saneamientos José Gómez S.L. | B5: Tienda de artículos de fontanería | C5: Av. Mare Nostrum, 41, 04009 Almería | D5: Almería | E5: Almería | F5: saneamientosjgomez.com | G5: 950 22 23 99 | H5: - | I5: =COUNTIF(Estadísticas!I:I,'centraldecomunicacion.es'!H5)>0 -> FALSE
A6: FONTANERÍA Y REFORMAS MIGUEL GARCÍA SERVIRAPID | B6: Fontanero | D6: Abla | G6: 670 50 94 30 | H6: - | I6: =COUNTIF(Estadísticas!I:I,'centraldecomunicacion.es'!H6)>0 -> FALSE
A7: Fontanería Eva Fontaneros | B7: Fontanero | C7: Calle Acacia, 8, 04240 Almería | D7: Almería | E7: Almería | F7: fontaneriaevaaguaygas.com | G7: 630 87 41 78 | H7: a36b86319e6542838a534122c8870e3f@sentry.qdqmedia.com | I7: =COUNTIF(Estadísticas!I:I,'centraldecomunicacion.es'!H7)>0 -> FALSE
A8: Fontanería Portocarrero | B8: Fontanero | C8: Calle Rosa Felices, Nº 134, 1º A, 04006 Almería | D8: Almería | E8: Almería | G8: 653 33 35 15 | H8: - | I8: =COUNTIF(Estadísticas!I:I,'centraldecomunicacion.es'!H8)>0 -> FALSE
A9: Saneamientos Jose Gomez SL | B9: Tienda de artículos de fontanería | C9: Calle Instinción, 2, 04006 Almería | D9: Almería | E9: Almería | F9: saneamientosjgomez.com | G9: 950 22 69 86 | H9: - | I9: =COUNTIF(Estadísticas!I:I,'centraldecomunicacion.es'!H9)>0 -> FALSE
A10: Saneamientos Alba | B10: Tienda de artículos de fontanería | C10: Calle Bidasoa, 6, 04006 Almería | D10: Almería | E10: Almería | F10: saneamientosalba.com | G10: 950 23 46 08 | H10: - | I10: =COUNTIF(Estadísticas!I:I,'centraldecomunicacion.es'!H10)>0 -> FALSE
A11: Fontanería Angel Nieto | B11: Fontanero | C11: Calle Calvario, 71, 04008 Almería | D11: Almería | E11: Almería | G11: 607 79 44 37 | H11: - | I11: =COUNTIF(Estadísticas!I:I,'centraldecomunicacion.es'!H11)>0 -> FALSE
A12: FONTANERÍA ERIKA | B12: Fontanero | C12: Plaza de los Oficios, 1, 04230 Huércal de Almería, Almería | D12: Huércal de Almería | E12: Almería | F12: fontaneriaerika.com | G12: 643 43 06 37 | H12: jlorenzofernandez32@gmail.com | I12: =COUNTIF(Estadísticas!I:I,'centraldecomunicacion.es'!H12)>0 -> TRUE
A13: ROTRISA S.L.U | B13: Tienda de artículos de fontanería | C13: Ctra. Sierra Alhamilla, 306, 04007 Almería | D13: Almería | E13: Almería | F13: rotrisa.com | G13: 950 22 03 11 | H13: cial@rotrisa.com | I13: =COUNTIF(Estadísticas!I:I,'centraldecomunicacion.es'!H13)>0 -> TRUE
A14: I.T. Fontelec | B14: Fontanero | C14: Calle Largo Caballero, 61, 04008 Almería | D14: Almería | E14: Almería | G14: 659 05 68 27 | H14: - | I14: =COUNTIF(Estadísticas!I:I,'centraldecomunicacion.es'!H14)>0 -> FALSE
A15: fontaneria salvador baena | B15: Fontanero | C15: Calle el Almendro, nº35, 04009 Almería | D15: Almería | E15: Almería | G15: 630 39 32 16 | H15: - | I15: =COUNTIF(Estadísticas!I:I,'centraldecomunicacion.es'!H15)>0 -> FALSE
A16: Fontanería Y Gas Luis Berenguel | B16: Fontanero | C16: Calle Jaúl, 1, 04007 Almería | D16: Almería | E16: Almería | G16: 617 44 71 22 | H16: - | I16: =COUNTIF(Estadísticas!I:I,'centraldecomunicacion.es'!H16)>0 -> FALSE
A17: Fontanería Uroz | B17: Fontanero | C17: Calle Poeta Luis Cernuda, 0, 04006 Almería | D17: Almería | E17: Almería | G17: 618 27 88 08 | H17: - | I17: =COUNTIF(Estadísticas!I:I,'centraldecomunicacion.es'!H17)>0 -> FALSE
A18: Fontaneria F.Delgado | B18: Fontanero | C18: Calle Real del Barrio Alto, 45, 04008 Almería | D18: Almería | E18: Almería | F18: fontaneriafdelgado.es | G18: 619 82 40 84 | H18: - | I18: =COUNTIF(Estadísticas!I:I,'centraldecomunicacion.es'!H18)>0 -> FALSE
A19: Fontaneros en Almería | Servicio Urgente y Económico en Zapillo | B19: Fontanero | D19: Abla | F19: fontaneroszapillo.com | G19: 658 68 89 62 | H19: tinfo@fontaneroszapillo.com | I19: =COUNTIF(Estadísticas!I:I,'centraldecomunicacion.es'!H19)>0 -> FALSE
A20: Multiservicios Fernández | B20: Fontanero | C20: Calle Gral. Luque, 36, 04002 Almería | D20: Almería | E20: Almería | F20: serviciosfernandez.es | G20: 604 18 15 94 | H20: info@serviciosfernandez.es | I20: =COUNTIF(Estadísticas!I:I,'centraldecomunicacion.es'!H20)>0 -> FALSE
A21: Comercial Maestria S.L. | B21: Tienda de artículos de fontanería | C21: Calle Maestría, 38, 04008 Almería | D21: Almería | E21: Almería | F21: fb.me | G21: 950 23 48 94 | H21: - | I21: =COUNTIF(Estadísticas!I:I,'centraldecomunicacion.es'!H21)>0 -> FALSE
A22: Fontaneria Puertas | B22: Fontanero | C22: Calle Cristóbal López Lupiañez, 04006 Almería | D22: Almería | E22: Almería | G22: 620 73 38 99 | H22: - | I22: =COUNTIF(Estadísticas!I:I,'centraldecomunicacion.es'!H22)>0 -> FALSE
A23: Fontanería Guillermo Cabeo | B23: Fontanero | D23: Abla | F23: facebook.com | G23: 607 60 71 36 | H23: - | I23: =COUNTIF(Estadísticas!I:I,'centraldecomunicacion.es'!H23)>0 -> FALSE
A24: INSTALACIONES &amp; REPARACIONES JOSÉ RODRIGUEZ | B24: Fontanero | C24: Calle Marchales, 90, bajo, 04008 Almería | D24: Almería | E24: Almería | G24: 607 18 76 62 | H24: - | I24: =COUNTIF(Estadísticas!I:I,'centraldecomunicacion.es'!H24)>0 -> FALSE
A25: Localización fugas de agua Almería | B25: Fontanero | C25: Calle la Plata, 33, 04008 Almería | D25: Almería | E25: Almería | G25: 950 14 15 94 | H25: - | I25: =COUNTIF(Estadísticas!I:I,'centraldecomunicacion.es'!H25)>0 -> FALSE
A26: Milán Fontaneros | B26: Fontanero | C26: C. Campogris, 33A, 04008 Almería | D26: Almería | E26: Almería | H26: - | I26: =COUNTIF(Estadísticas!I:I,'centraldecomunicacion.es'!H26)>0 -> FALSE
A27: fontaneria saez | B27: Fontanero | C27: Calle Cámaras, 22, 04003 Almería | D27: Almería | E27: Almería | F27: fontaneriasaezalmeria.com | G27: 950 26 71 58 | H27: - | I27: =COUNTIF(Estadísticas!I:I,'centraldecomunicacion.es'!H27)>0 -> FALSE
A28: VALSAN Delegación ALMERÍA | B28: Tienda de artículos de fontanería | C28: Calle Carbon, 121, 04009 Almería | D28: Almería | E28: Almería | F28: valsan.es | G28: 950 17 35 91 | H28: ventas@valsan.es | I28: =COUNTIF(Estadísticas!I:I,'centraldecomunicacion.es'!H28)>0 -> FALSE
A29: Intec Climatizacion-Electricidad-Fontaneria | B29: Fontanero | C29: Calle Estaño, 04009 Almería | D29: Almería | E29: Almería | H29: - | I29: =COUNTIF(Estadísticas!I:I,'centraldecomunicacion.es'!H29)>0 -> FALSE
A30: Fontanería M&amp;R | B30: Fontanero | C30: Av. de Cabo de Gata, 88, 04007 Almería | D30: Almería | E30: Almería | F30: fontaneria-mr.negocio.site | H30: - | I30: =COUNTIF(Estadísticas!I:I,'centraldecomunicacion.es'!H30)>0 -> FALSE
A31: Albanileria Y Fontanería | B31: Fontanero | C31: Calle Plus Ultra, 9, 04005 Almería | D31: Almería | E31: Almería | H31: - | I31: =COUNTIF(Estadísticas!I:I,'centraldecomunicacion.es'!H31)>0 -> FALSE
A32: Localización y Detección de Fugas Almeria | B32: Fontanero | C32: Calle Maldonado Entrena bloque 2-4, 5ª puerta, 04003 Almería | D32: Almería | E32: Almería | F32: grupovico.com | G32: 627 42 10 32 | H32: info@grupovico.com | I32: =COUNTIF(Estadísticas!I:I,'centraldecomunicacion.es'!H32)>0 -> FALSE
A33: Fontaneria Fortuna | B33: Fontanero | C33: Calle Pedro Jover, 8, 04002 Almería | D33: Almería | E33: Almería | H33: - | I33: =COUNTIF(Estadísticas!I:I,'centraldecomunicacion.es'!H33)>0 -> FALSE
A34: Gas Fellas Plumber Almeria | B34: Fontanero | C34: Calle Navarro Rodrigo, 8, 4D, 04001 Almería | D34: Almería | E34: Almería | F34: gasfellas.com | G34: 911 23 25 18 | H34: - | I34: =COUNTIF(Estadísticas!I:I,'centraldecomunicacion.es'!H34)>0 -> FALSE
A35: Reparaciones Urgencias Almería | B35: Fontanero | C35: Plaza Carabineros, 14, 04007 Almería | D35: Almería | E35: Almería | F35: reparacionesurgencias.online | G35: 950 95 56 64 | H35: Contacto@servicioshogaralmeria.es | I35: =COUNTIF(Estadísticas!I:I,'centraldecomunicacion.es'!H35)>0 -> FALSE
A36: YAVAMOS | B36: Fontanero | C36: Calle Búfalo, 42, 04720 Aguadulce, Almería | D36: Aguadulce | E36: Almería | F36: yavamos.es | G36: 950 65 34 06 | H36: core-js-bundle@3.2.1 | I36: =COUNTIF(Estadísticas!I:I,'centraldecomunicacion.es'!H36)>0 -> FALSE
A37: Materiales y Sistemas de Calefacción S.L. | B37: Fontanero | C37: Polígono Industrial Mezquita, 398, 04007 Almería | D37: Almería | E37: Almería | G37: 950 22 74 50 | H37: - | I37: =COUNTIF(Estadísticas!I:I,'centraldecomunicacion.es'!H37)>0 -> FALSE
A38: Oil Barol | B38: Fontanero | C38: Calle Vélez Rubio, 04001 Almería | D38: Almería | E38: Almería | H38: - | I38: =COUNTIF(Estadísticas!I:I,'centraldecomunicacion.es'!H38)>0 -> FALSE
A39: Almería AguaConfort S.L. (Tienda en Almería Capital) | B39: Tienda de artículos de fontanería | C39: Carretera Níjar - la Cañada, nº398, 04007 Almería | D39: Almería | E39: Almería | F39: grupoaguaconfort.com | G39: 950 22 79 00 | H39: core-js-bundle@3.2.1 | I39: =COUNTIF(Estadísticas!I:I,'centraldecomunicacion.es'!H39)>0 -> FALSE
A40: Fontanería Cabrera | B40: Fontanero | C40: Calle Gardenia, 6, 04720 Aguadulce, Almería | D40: Aguadulce | E40: Almería | F40: fontaneroalmeria.business.site | G40: 950 34 26 61 | H40: - | I40: =COUNTIF(Estadísticas!I:I,'centraldecomunicacion.es'!H40)>0 -> FALSE
...

Sheet Estadísticas
A1: Número de empresas | B1: Número de correos electrónicos | C1: Número de webs | D1: Números de teléfono | E1: Números de teléfono fijo | F1: Números de teléfono móvil | G1: Sectores | H1: Mails únicos | I1: Mails verificados
A2: =COUNTIF('centraldecomunicacion.es'!A2:'centraldecomunicacion.es'!A19470,"*") -> 4836 | B2: =COUNTIF('centraldecomunicacion.es'!H2:'centraldecomunicacion.es'!H19470,"*@*") -> 1124 | C2: =COUNTIF('centraldecomunicacion.es'!F2:'centraldecomunicacion.es'!F19470,"*.*") -> 1957 | D2: =COUNTIF('centraldecomunicacion.es'!G2:'centraldecomunicacion.es'!G19470,"6*")+COUNTIF('centraldecomunicacion.es'!G2:'centraldecomunicacion.es'!G19470,"9*") -> 3997 | E2: =COUNTIF('centraldecomunicacion.es'!G2:'centraldecomunicacion.es'!G19470,"9*") -> 2116 | F2: =COUNTIF('centraldecomunicacion.es'!G2:'centraldecomunicacion.es'!G19470,"6*") -> 1881 | G2: {=_xlfn.UNIQUE('centraldecomunicacion.es'!B2:'centraldecomunicacion.es'!B19470)} -> Fontanero | H2: {=_xlfn.UNIQUE('centraldecomunicacion.es'!H2:'centraldecomunicacion.es'!H19470)} -> - | I2: jlorenzofernandez32@gmail.com
G3: Tienda de artículos de fontanería | H3: info@aquagasalmeria.es | I3: cial@rotrisa.com
G4: Fontanería | H4: info@fontaneriaignaciogonzalez.es | I4: rafaellopez@rlopezm.com
G5: 0 | H5: a36b86319e6542838a534122c8870e3f@sentry.qdqmedia.com | I5: servicios@schogar.com
H6: jlorenzofernandez32@gmail.com | I6: fontaclima@hotmail.es
H7: cial@rotrisa.com | I7: altamiranosl@live.com
H8: tinfo@fontaneroszapillo.com | I8: jose.m.sanchez.paya@gmail.com
H9: info@serviciosfernandez.es | I9: suinprosur@suinprosur.es
H10: ventas@valsan.es | I10: desatascosomega@gmail.com
H11: info@grupovico.com | I11: fugascor@gmail.com
H12: Contacto@servicioshogaralmeria.es | I12: esmebra@esmebra.com
H13: core-js-bundle@3.2.1 | I13: fontaneriaygasandalucia@gmail.com
H14: rafaellopez@rlopezm.com | I14: sanealuque@hotmail.com
H15: servicios@schogar.com | I15: canalcor@hotmail.com
H16: web@fontarboleas.es | I16: revestimiento@revestimientosjulio.es
H17: fontaclima@hotmail.es | I17: fontaneroscordoba@gmail.com
... H313: tecnico@fontaneriafontcal.com | I313: fmatiena@euskalnet.net
H314: contacto@fontaneriaycalefaccionguarnizo.com
H315: info@grupodelavega.es
H316: aguasexpert@hotmail.com
H317: briccal@briccal.com
H318: fontaneriamuskiz@gmail.com
H319: alexruizgomez1975@gmail.com
H320: AZCONAFONTANERIA@GMAIL.COM
H321: administracion@dayvo.com
H322: info@fontaneriabizkaia.com
H323: cyfgomezbravo@gmail.com
H324: gpodena@gmail.com
H325: info@masqueduchas.com
... H881: fmatiena@euskalnet.net
H882: 0

Sheet Copyright
A1: Esta base de datos de empresas se encuentra protegida bajo derechos de autor. Está prohibida su copia y reproducción con o sin ánimo de lucro bajo autorización expresa del autor según artículo 270, 270.2, 270.3, 270.4, 270.5, 270.6, 270.7 Como medida de seguridad hay registros clave a modo de firma digital registrados ante notario y ante la consejería de cultura y patrimonio histórico con número GR-00416-2020
