Workbook

Sheet Centraldecomunicacion.es
A1: ﻿Nombre | B1: Categoría | C1: Direccion | D1: Localidad | E1: Provincia | F1: Website | G1: Teléfono | H1: email | I1: mail verificado
A2: Herbolario Ángel | B2: Herbolario | C2: C. José Artés de Arcos, 15, 04004 Almería | D2: Almería | E2: Almería | F2: herbolarioangel.net | G2: 950 26 24 39 | H2: - | I2: =COUNTIF(Estadísticas!I:I,'Centraldecomunicacion.es'!H2)>0 -> FALSE
A3: Herbolario El Agape | B3: Herbolario | C3: C. Granada, 185, 04008 Almería | D3: Almería | E3: Almería | F3: herbolarioelagape.es | G3: 658 93 56 36 | H3: info@herbolarioelagape.es | I3: =COUNTIF(Estadísticas!I:I,'Centraldecomunicacion.es'!H3)>0 -> FALSE
A4: HERBOLARIO DE LORIEN | B4: Herbolario | C4: Av. de Cabo de Gata, 139, 04007 Almería | D4: Almería | E4: Almería | G4: 950 08 83 69 | H4: - | I4: =COUNTIF(Estadísticas!I:I,'Centraldecomunicacion.es'!H4)>0 -> FALSE
A5: Herbolario HIERBA LUISA | B5: Herbolario | C5: C. Juan Leal, 2, 04001 Almería | D5: Almería | E5: Almería | G5: 950 23 98 57 | H5: - | I5: =COUNTIF(Estadísticas!I:I,'Centraldecomunicacion.es'!H5)>0 -> FALSE
A6: Herbolario Alonso | B6: Herbolario | C6: C. el Alcázar, 28, 04006 Almería | D6: Almería | E6: Almería | G6: 657 27 73 16 | H6: - | I6: =COUNTIF(Estadísticas!I:I,'Centraldecomunicacion.es'!H6)>0 -> FALSE
A7: Bio Amapola Amapola | B7: Herbolario | C7: C. Amapola, 11, 04004 Almería | D7: Almería | E7: Almería | G7: 950 25 33 65 | H7: - | I7: =COUNTIF(Estadísticas!I:I,'Centraldecomunicacion.es'!H7)>0 -> FALSE
A8: Herbolario Mirto | B8: Herbolario | C8: C. Perdiz, 15, 04009 Almería | D8: Almería | E8: Almería | G8: 950 03 57 11 | H8: - | I8: =COUNTIF(Estadísticas!I:I,'Centraldecomunicacion.es'!H8)>0 -> FALSE
A9: Herbolario y Estética Natural Azalea Lives | B9: Herbolario | C9: Calle Dr. Giménez Canga Argüelles, 5, 04005 Almería | D9: Almería | E9: Almería | F9: azalealives.com | G9: 611 44 35 64 | H9: Info@azalealives.com | I9: =COUNTIF(Estadísticas!I:I,'Centraldecomunicacion.es'!H9)>0 -> FALSE
A10: Herbolario Almería Natural | B10: Herbolario | C10: Carrera del Mami, 7, 04009 Almería | D10: Almería | E10: Almería | G10: 622 23 96 31 | H10: - | I10: =COUNTIF(Estadísticas!I:I,'Centraldecomunicacion.es'!H10)>0 -> FALSE
A11: Campos de Aloe | B11: Herbolario | C11: Av. de la Estación, 25, 04005 Almería | D11: Almería | E11: Almería | G11: 950 22 63 17 | H11: - | I11: =COUNTIF(Estadísticas!I:I,'Centraldecomunicacion.es'!H11)>0 -> FALSE
A12: Rafael Díaz García | B12: Herbolario | C12: C. Altamira, 9, 04005 Almería | D12: Almería | E12: Almería | G12: 950 26 99 69 | H12: - | I12: =COUNTIF(Estadísticas!I:I,'Centraldecomunicacion.es'!H12)>0 -> FALSE
A13: Herboristeria Casa Elo | B13: Herbolario | C13: Calle Dr. Gregorio Marañón, 10, 04005 Almería | D13: Almería | E13: Almería | G13: 950 25 80 21 | H13: - | I13: =COUNTIF(Estadísticas!I:I,'Centraldecomunicacion.es'!H13)>0 -> FALSE
A14: Herbolario Farmaline | B14: Herbolario | C14: Av. de Cabo de Gata, 115, 04007 Almería | D14: Almería | E14: Almería | F14: business.site | G14: 686 00 72 85 | H14: - | I14: =COUNTIF(Estadísticas!I:I,'Centraldecomunicacion.es'!H14)>0 -> FALSE
A15: HERBOLANIC NATURAL | B15: Herbolario | C15: Av. de Pablo Iglesias, 55, LOCAL, 04003 Almería | D15: Almería | E15: Almería | F15: herbolanic.com | G15: 634 49 37 44 | H15: - | I15: =COUNTIF(Estadísticas!I:I,'Centraldecomunicacion.es'!H15)>0 -> FALSE
A16: onnea concept | B16: Herbolario | C16: C. Benizalón, 3, 04007 Almería | D16: Almería | E16: Almería | G16: 692 91 79 60 | H16: - | I16: =COUNTIF(Estadísticas!I:I,'Centraldecomunicacion.es'!H16)>0 -> FALSE
A17: HERBOLARIO LA MILAGROSA | B17: Herbolario | C17: Ctra.Almeria, Urb.El Cercado, 132, 04230 Huércal de Almería, Almería | D17: Huércal de Almería | E17: Almería | F17: herbolariolamilagrosa.com | G17: 667 63 02 58 | H17: - | I17: =COUNTIF(Estadísticas!I:I,'Centraldecomunicacion.es'!H17)>0 -> FALSE
A18: Virtual Data SLU | B18: Herbolario | C18: Av. de Cabo de Gata, 139, 04007 Almería | D18: Almería | E18: Almería | G18: 950 08 83 69 | H18: - | I18: =COUNTIF(Estadísticas!I:I,'Centraldecomunicacion.es'!H18)>0 -> FALSE
A19: Herbolario | B19: Herbolario | C19: Pl. Antonio de Torres, 7, 04120 La Cañada, Almería | D19: La Cañada | E19: Almería | G19: 950 29 20 61 | H19: - | I19: =COUNTIF(Estadísticas!I:I,'Centraldecomunicacion.es'!H19)>0 -> FALSE
A20: Mar Natura Herbolario | B20: Herbolario | C20: C. Solidaridad, 1, 04130 El Alquián, Almería | D20: El Alquián | E20: Almería | G20: 609 11 76 70 | H20: - | I20: =COUNTIF(Estadísticas!I:I,'Centraldecomunicacion.es'!H20)>0 -> FALSE
A21: HERBOLARIO LA VENTANA NATURAL | B21: Herbolario | C21: Cam. de los Parrales, 338, 04720 Aguadulce, Almería | D21: Aguadulce | E21: Almería | F21: laventananatural.com | G21: 665 53 05 11 | H21: contacto@laventananatural.com | I21: =COUNTIF(Estadísticas!I:I,'Centraldecomunicacion.es'!H21)>0 -> FALSE
A22: Herbolario Mentadulce | B22: Herbolario | C22: Carr de Alicún, 26, 04740 Roquetas de Mar, Almería | D22: Roquetas de Mar | E22: Almería | G22: 950 32 11 57 | H22: - | I22: =COUNTIF(Estadísticas!I:I,'Centraldecomunicacion.es'!H22)>0 -> FALSE
A23: Herbolario Silvestre | B23: Herbolario | C23: C. Manuel Machado, 45, 04740 Roquetas de Mar, Almería | D23: Roquetas de Mar | E23: Almería | G23: 950 32 10 46 | H23: - | I23: =COUNTIF(Estadísticas!I:I,'Centraldecomunicacion.es'!H23)>0 -> FALSE
A24: Parafarmacia Herbolario | B24: Herbolario | C24: C. Carlos Arniches, 04720 El Parador de las Hortichuelas, Almería | D24: El Parador de las Hortichuelas | E24: Almería | G24: 950 34 15 42 | H24: - | I24: =COUNTIF(Estadísticas!I:I,'Centraldecomunicacion.es'!H24)>0 -> FALSE
A25: Herbolario El Jardin De La Salud | B25: Herbolario | C25: Av. Reino de España, 35, 04740 Roquetas de Mar, Almería | D25: Roquetas de Mar | E25: Almería | G25: 950 53 31 26 | H25: - | I25: =COUNTIF(Estadísticas!I:I,'Centraldecomunicacion.es'!H25)>0 -> FALSE
A26: Herboristería, tienda esotérica y artículos de regalo El secreto | B26: Herbolario | C26: Av. de Carlos III, 447, 04720 Aguadulce, Almería | D26: Aguadulce | E26: Almería | G26: 615 98 36 74 | H26: - | I26: =COUNTIF(Estadísticas!I:I,'Centraldecomunicacion.es'!H26)>0 -> FALSE
A27: Bottega Verde | B27: Herbolario | C27: Carretera Roquetas - Alicun, 0 S/N, 04740 Roquetas de Mar, Almería | D27: Roquetas de Mar | E27: Almería | G27: 950 32 95 49 | H27: - | I27: =COUNTIF(Estadísticas!I:I,'Centraldecomunicacion.es'!H27)>0 -> FALSE
A28: Herbolario Jazmín | B28: Herbolario | C28: Av. de las Marinas, 209, 04740 Roquetas de Mar, Almería | D28: Roquetas de Mar | E28: Almería | G28: 630 53 89 82 | H28: - | I28: =COUNTIF(Estadísticas!I:I,'Centraldecomunicacion.es'!H28)>0 -> FALSE
A29: HERBAL PHARMACY | B29: Herbolario | C29: Av. de Juan Bonachera, 24, 04740 Roquetas de Mar, Almería | D29: Roquetas de Mar | E29: Almería | G29: 698 51 29 08 | H29: - | I29: =COUNTIF(Estadísticas!I:I,'Centraldecomunicacion.es'!H29)>0 -> FALSE
A30: Herbolario Almerinatur | B30: Herbolario | C30: C. Fragata, 10, 04711 Almerimar, Almería | D30: Almerimar | E30: Almería | G30: 950 49 78 12 | H30: - | I30: =COUNTIF(Estadísticas!I:I,'Centraldecomunicacion.es'!H30)>0 -> FALSE
A31: Tara Natura | B31: Herbolario | C31: Cjón. de Istria, 38, 04118 San José, Almería | D31: San José | E31: Almería | G31: 669 49 64 13 | H31: - | I31: =COUNTIF(Estadísticas!I:I,'Centraldecomunicacion.es'!H31)>0 -> FALSE
A32: Herbolario Mary | B32: Herbolario | C32: C. Murgis, 15, 04700 El Ejido, Almería | D32: El Ejido | E32: Almería | F32: herbolariomary.es | G32: 950 48 03 63 | H32: info@herbolariomary.es | I32: =COUNTIF(Estadísticas!I:I,'Centraldecomunicacion.es'!H32)>0 -> FALSE
A33: La Botica de Fuen | B33: Herbolario | C33: C. Infanta Elena, 5, 04745 La Mojonera, Almería | D33: La Mojonera | E33: Almería | G33: 950 33 03 84 | H33: - | I33: =COUNTIF(Estadísticas!I:I,'Centraldecomunicacion.es'!H33)>0 -> FALSE
A34: Saica Natur S.L. | B34: Herbolario | C34: Ctra de la Mojonera a San Agustín, 04745 Mojonera (la), Almería | D34: Abla | E34: Almería | G34: 950 60 33 38 | H34: - | I34: =COUNTIF(Estadísticas!I:I,'Centraldecomunicacion.es'!H34)>0 -> FALSE
A35: Herbolario Mary | B35: Herbolario | C35: P.º Alcalde Garcia Acien, 9, 04700 El Ejido, Almería | D35: El Ejido | E35: Almería | F35: herbolariomary.es | G35: 950 48 71 63 | H35: - | I35: =COUNTIF(Estadísticas!I:I,'Centraldecomunicacion.es'!H35)>0 -> FALSE
A36: Herbolario Elisa | B36: Herbolario | C36: C. Gustavo Adolfo Bécquer, 9, 04700 El Ejido, Almería | D36: El Ejido | E36: Almería | F36: herbolarioelisa.com | G36: 950 57 06 85 | H36: - | I36: =COUNTIF(Estadísticas!I:I,'Centraldecomunicacion.es'!H36)>0 -> FALSE
A37: Herboristeria Carmen Ramos | B37: Herbolario | C37: C. Aljibe, 2, 04110 Campohermoso, Almería | D37: Campohermoso | E37: Almería | G37: 627 83 43 41 | H37: - | I37: =COUNTIF(Estadísticas!I:I,'Centraldecomunicacion.es'!H37)>0 -> FALSE
A38: Herbolisteria | B38: Herbolario | C38: Blvr. de el Ejido, 445, 04700 El Ejido, Almería | D38: El Ejido | E38: Almería | H38: - | I38: =COUNTIF(Estadísticas!I:I,'Centraldecomunicacion.es'!H38)>0 -> FALSE
A39: Herbolario Naturdivina Carboneras | B39: Herbolario | C39: C. Plus Ultra, 37, 04140 Carboneras, Almería | D39: Carboneras | E39: Almería | G39: 693 69 08 55 | H39: - | I39: =COUNTIF(Estadísticas!I:I,'Centraldecomunicacion.es'!H39)>0 -> FALSE
A40: herbolario la Jara de Ana | B40: Herbolario | C40: parque comercial Mojácar playa local bajo, 4, 04638 Mojácar, Almería | D40: Mojácar | E40: Almería | G40: 950 47 25 59 | H40: - | I40: =COUNTIF(Estadísticas!I:I,'Centraldecomunicacion.es'!H40)>0 -> FALSE
...

Sheet Estadísticas
A1: Número de empresas | B1: Número de correos electrónicos | C1: Número de webs | D1: Números de teléfono | E1: Números de teléfono fijo | F1: Números de teléfono móvil | G1: Sectores | H1: Mails únicos | I1: Mails verificados
A2: =COUNTIF('Centraldecomunicacion.es'!A2:'Centraldecomunicacion.es'!A19470,"*") -> 2271 | B2: =COUNTIF('Centraldecomunicacion.es'!H2:'Centraldecomunicacion.es'!H19470,"*@*") -> 580 | C2: =COUNTIF('Centraldecomunicacion.es'!F2:'Centraldecomunicacion.es'!F19470,"*.*") -> 856 | D2: =COUNTIF('Centraldecomunicacion.es'!G2:'Centraldecomunicacion.es'!G19470,"6*")+COUNTIF('Centraldecomunicacion.es'!G2:'Centraldecomunicacion.es'!G19470,"9*") -> 2057 | E2: =COUNTIF('Centraldecomunicacion.es'!G2:'Centraldecomunicacion.es'!G19470,"9*") -> 1608 | F2: =COUNTIF('Centraldecomunicacion.es'!G2:'Centraldecomunicacion.es'!G19470,"6*") -> 449 | G2: {=_xlfn.UNIQUE('Centraldecomunicacion.es'!B2:'Centraldecomunicacion.es'!B19470)} -> Herbolario | H2: {=_xlfn.UNIQUE('Centraldecomunicacion.es'!H2:'Centraldecomunicacion.es'!H19470)} -> - | I2: santiverialgeciras@gmail.com
G3: 0 | H3: info@herbolarioelagape.es | I3: mundoherbolariocordoba@gmail.com
H4: Info@azalealives.com | I4: service.consommateur@daregal.fr
H5: contacto@laventananatural.com | I5: herbolariomontoro@casmasalud.es
H6: info@herbolariomary.es | I6: pedidos@aceitesansorena.com
H7: info@pharmaherbal.es | I7: granadiet@granadiet.com
H8: su@email.com | I8: herbolarioespacionatura@gmail.com
H9: info@centrodieteticoviquez.com | I9: herbolariolaspezia@gmail.com
H10: info@amanecerdedia.com | I10: franciscojose.moreno@gmail.com
H11: contacto@ladespensadegaia.com | I11: natural@herbolariomadrenaturaleza.com
H12: info@vidamassana.com | I12: centrointernacionaldedietetica@gmail.com
H13: informacion@santiveri.es | I13: mercado@zurcanatural.com
H14: info@saludnaturalparati.com | I14: marisolesencia@gmail.com
H15: support@webnode.es | I15: mapielena@hotmail.com
... H102: ceresherbal@hotmail.com | I102: bizilegorreta@gmail.com
H103: info@herbolariosdoemi.com
H104: info@anemonaherbolario.com
H105: boticadecarmenoviedo@gmail.com
H106: herbosura@gmail.com
H107: herboristeriarobledo@hotmail.com
H108: info@dieteticoastur.com
H109: info@hierbabuenadiet.com
H110: info@herbolarioelxabu.com
H111: sanabel@sanabel.com.es
H112: eltilar@herbolarioeltilar.com
H113: press@google.com
H114: info@plantasanagijon.com
... H392: info@amalurbelardenda.com
H393: 0

Sheet Copyright
A1: Esta base de datos de empresas se encuentra protegida bajo derechos de autor. Está prohibida su copia y reproducción con o sin ánimo de lucro bajo autorización expresa del autor según artículo 270, 270.2, 270.3, 270.4, 270.5, 270.6, 270.7 Como medida de seguridad hay registros clave a modo de firma digital registrados ante notario y ante la consejería de cultura y patrimonio histórico con número GR-00416-2020

Sheet Leads verificados
A1: ﻿Nombre | B1: Categoría | C1: Direccion | D1: Localidad | E1: Provincia | F1: Website | G1: Teléfono | H1: email | I1: mail verificado
A2: SANTIVERI | B2: Herbolario | C2: C. Alfonso XI, 15, BAJO, 11201 Algeciras, Cádiz | D2: Algeciras | E2: Cádiz | F2: santiverialgeciras.com | G2: 956 66 39 67 | H2: santiverialgeciras@gmail.com | I2: TRUE
A3: Mundo Herbolario | B3: Herbolario | C3: Calle Isla Formentera &amp;, Gta. Amadora, 14011 Córdoba | D3: Córdoba | E3: Córdoba | F3: mundoherbolariocordoba.es | G3: 957 04 35 37 | H3: mundoherbolariocordoba@gmail.com | I3: TRUE
A4: Darégal | B4: Herbolario | C4: Carretera Aldea Quintana Puente Genil, 0 Km 42 5 ( A-379 ), 14546 Santaella, Córdoba | D4: Santaella | E4: Córdoba | F4: daregal.fr | G4: 957 31 33 55 | H4: service.consommateur@daregal.fr | I4: TRUE
A5: Herbolario CasmaSalud | B5: Herbolario | C5: C. Cervantes, 17, Local Izqda, 14600 Montoro, Córdoba | D5: Montoro | E5: Córdoba | F5: casmasalud.es | G5: 957 16 24 15 | H5: herbolariomontoro@casmasalud.es | I5: TRUE
A6: ACEITES ANSORENA &amp; ASOC. S.L. | B6: Herbolario | C6: C. del Aceite, 7, 14850 Baena, Córdoba | D6: Baena | E6: Córdoba | F6: aceitesansorena.com | G6: 957 67 05 84 | H6: pedidos@aceitesansorena.com | I6: TRUE
A7: Herbolarios Granadiet Martínez Campos | B7: Herbolario | C7: C. Martínez Campos, nº11, 18002 Granada | D7: Granada | E7: Granada | F7: granadiet.com | G7: 958 08 22 72 | H7: granadiet@granadiet.com | I7: TRUE
A8: Espacio Natura Herbolario | B8: Herbolario | C8: Calle Dr. Barraquer, 1, 3, 18220 Albolote, Granada | D8: Albolote | E8: Granada | F8: espacionaturaherbolario.com | G8: 958 04 23 38 | H8: herbolarioespacionatura@gmail.com | I8: TRUE
A9: El Herbolario la Spezia | B9: Herbolario | C9: C. de la Cárcel, 4, 18230 Atarfe, Granada | D9: Atarfe | E9: Granada | F9: elherbolarionatural.es | G9: 670 06 54 86 | H9: herbolariolaspezia@gmail.com | I9: TRUE
A10: Herbolario &quot;Equinácea&quot; | B10: Herbolario | C10: C. Berdigón, 18, 21003 Huelva | D10: Huelva | E10: Huelva | F10: herbolarioequinacea.com | G10: 959 24 68 84 | H10: franciscojose.moreno@gmail.com | I10: TRUE
A11: HERBOLARIO MADRE NATURALEZA- ISLA CHICA HUELVA | B11: Herbolario | C11: Isla Chica enfrente del Bar San Ramón, C. Manuel Sánchez, 13, 21006 Huelva | D11: Huelva | E11: Huelva | F11: herbolariomadrenaturaleza.com | G11: 641 79 43 85 | H11: natural@herbolariomadrenaturaleza.com | I11: TRUE
A12: Centro Internacional de Dietética | B12: Herbolario | C12: C. Niebla, 1, BAJO, 21007 Huelva | D12: Huelva | E12: Huelva | F12: centrointernacionaldedietetica.com | G12: 959 22 20 48 | H12: centrointernacionaldedietetica@gmail.com | I12: TRUE
A13: ZURCA Mercado Natural. ✅ Tienda de Productos Ecológicos. Herbolario. | B13: Herbolario | C13: Av. del Mediterráneo, 119, A, 29730 Rincón de la Victoria, Málaga | D13: Rincón de la Victoria | E13: Málaga | F13: zurcanatural.com | G13: 657 32 31 34 | H13: mercado@zurcanatural.com | I13: TRUE
... A28: HERBOLARIO GAROE | B28: Herbolario | C28: Multicentro Club, Av. Juan Carlos I, 6, 38650 Los Cristianos, Santa Cruz de Tenerife | D28: Los Cristianos | E28: Santa Cruz de Tenerife | F28: herbolariogaroe.com | G28: 922 75 20 71 | H28: herbolariogaroe@hotmail.es | I28: TRUE
A29: El Camino The Way Herbolario Online | B29: Herbolario | D29: Adeje | F29: elcaminotheway.shop | H29: THEWAY.2020PARAFARMACIAHERBOLARIO@HOTMAIL.COM | I29: TRUE
A30: Herbolario Nueva Luna | B30: Herbolario | C30: Av. San Francisco, 6, 38650 Los Cristianos, Santa Cruz de Tenerife | D30: Los Cristianos | E30: Santa Cruz de Tenerife | F30: herbolariosenloscristianos.com | G30: 922 78 99 90 | H30: pibotto@hotmail.com | I30: TRUE
A31: HERBALIFE. Dist.Independiente en Tenerife | B31: Herbolario | C31: Calle del Dr. Ingram, 8, 38400 Puerto de la Cruz, Santa Cruz de Tenerife | D31: Puerto de la Cruz | E31: Santa Cruz de Tenerife | F31: mantentufigura.com | G31: 637 27 46 23 | H31: cbherbal@hotmail.com | I31: TRUE
A32: Herbolario Salud y Belleza | B32: Herbolario | C32: TF-28, 115, 38626 Valle de San Lorenzo, Santa Cruz de Tenerife | D32: Valle de San Lorenzo | E32: Santa Cruz de Tenerife | F32: saludybellezatenerife.es | G32: 922 72 23 78 | H32: esperanzabergaz@hotmail.com | I32: TRUE
A33: Salud en Casa! | B33: Herbolario | C33: San Isidro 6, 38611 San Isidro, Santa Cruz de Tenerife | D33: San Isidro | E33: Santa Cruz de Tenerife | F33: saludencasa.ueniweb.com | G33: 633 77 01 43 | H33: antonia_crespo_martin@hotmail.com | I33: TRUE
A34: Herbolario Jeler | B34: Herbolario | C34: C. la Industria, 5, 39610 Astillero, Cantabria | D34: Astillero | E34: Cantabria | F34: herbolariojeler.com | G34: 942 54 27 24 | H34: maite.terapiasnaturales@hotmail.com | I34: TRUE
A35: Azu Factoría Natural | B35: Herbolario | C35: Bo. las Escuelas, 17, B, 39608 Igollo de Camargo, Cantabria | D35: Igollo de Camargo | E35: Cantabria | F35: azufactorianatural.com | G35: 608 27 63 56 | H35: Factorianatural@gmail.com | I35: TRUE
A36: Herbolario Mayor | B36: Herbolario | C36: C. Mayor, 40, 02002 Albacete | D36: Albacete | E36: Albacete | F36: ecoherbolariomayor.com | G36: 967 18 92 86 | H36: tienda@ecoherbolariomayor.com | I36: TRUE
A37: HERBOLARIO SOL Y TIERRA | B37: Herbolario | C37: C. de Alarcos, 13, 13001 Ciudad Real, Cdad. Real | D37: Ciudad Real | E37: Cdad. Real | F37: herbolariosolytierra.es | G37: 926 21 13 98 | H37: tiendaonline@herbolariosolytierra.es | I37: TRUE
A38: Herbolario Puertovera | B38: Herbolario | C38: C. Alejandro Prieto, 10, 13500 Puertollano, Cdad. Real | D38: Puertollano | E38: Cdad. Real | F38: puertovera.com | G38: 926 43 10 09 | H38: pedidos@puertovera.com | I38: TRUE
A39: Herboristería Ginkgo Biloba | B39: Herbolario | C39: C. Don Juan de Austria, 5, BAJO, 13630 Socuéllamos, Cdad. Real | D39: Socuéllamos | E39: Cdad. Real | F39: herboristeriaginkgobiloba.com | G39: 926 53 18 23 | H39: loren-carrasco@herboristeriaginkgobiloba.com | I39: TRUE
A40: Herbolario Hierbabuena | B40: Herbolario | C40: Pl. Cdad. de Nara N2, Módulo 2, Local 34, 45005 Toledo | D40: Toledo | E40: Toledo | F40: herbolariotoledo.com | G40: 644 27 17 58 | H40: herbolariotoledo@gmail.com | I40: TRUE
A41: STEVIA HERBOLARIO Y CENTRO TERAPIAS | B41: Herbolario | C41: herbolario, C. Beato Juan de Ávila, 5, 45510 Fuensalida, Toledo | D41: Fuensalida | E41: Toledo | F41: xalumedix.com | G41: 925 71 14 41 | H41: xalumedix@xalumedix.com | I41: TRUE
... A71: Más Cuidarse | B71: Herbolario | C71: Av. de la Ribera Alta, 12, Bajo Izquierda, 46260 Alberic, Valencia, Valencia | D71: Alberique | E71: Valencia | F71: mascuidarse.es | G71: 644 43 69 93 | H71: mascuidarse@gmail.com | I71: TRUE
A72: Pharmalife | B72: Herbolario | C72: Calle, Pl. Constitución, 06480 Montijo, Badajoz | D72: Montijo | E72: Badajoz | F72: pharmalife.ueniweb.com | H72: lperezm6644@hotmail.com | I72: TRUE
A73: Ecoespazo VITRIOL | B73: Herbolario | C73: Rúa Diego Pazos, 18, 27600 Sarria, Lugo | D73: Sarria | E73: Lugo | F73: ecoespazovitriol.com | G73: 982 88 66 16 | H73: ecoespazovitriol@gmail.com | I73: TRUE
A74: Milhflor | B74: Herbolario | C74: Cardenal de Quevedo, 4, 32004 Ourense, Province of Ourense | D74: Ourense | E74: Province of Ourense | F74: milhflor.com | G74: 988 24 92 45 | H74: tienda@milhflor.com | I74: TRUE
A75: El Bazar Natural ® | B75: Herbolario | C75: Ourense, 32830 Ourense | D75: Ourense | E75: Ourense | F75: elbazarnatural.com | G75: 988 54 42 00 | H75: correo@elbazarnatural.com | I75: TRUE
A76: Centro Dietético Hortelán Moaña | B76: Herbolario | C76: Av. de Concepción Arenal, 220, 36959 Moaña, Pontevedra | D76: Moaña | E76: Pontevedra | F76: hortelan.com | G76: 986 31 54 64 | H76: herbolario@hortelan.com | I76: TRUE
A77: Eco Cash | B77: Herbolario | C77: Rúa Cunchido de Arriba, nº1, 36940 Darbo, Pontevedra | D77: Darbo | E77: Pontevedra | F77: ecocash.es | G77: 986 30 23 43 | H77: david@ecocash.es | I77: TRUE
A78: ELIXIR BIOTIENDA | B78: Herbolario | C78: Rúa México, 62, 36204 Vigo, Pontevedra | D78: Vigo | E78: Pontevedra | F78: elixirbiotienda.es | G78: 630 03 04 56 | H78: elixirbiotienda@gmail.com | I78: TRUE
A79: Exialoe - Productos Naturales con Aloe Vera | B79: Herbolario | C79: Calle Monte del Sino, 29, 36206 Vigo, Pontevedra | D79: Vigo | E79: Pontevedra | F79: exialoe.es | G79: 607 39 92 84 | H79: aloe@euroexito.com | I79: TRUE
A80: Hierbabuena Herbolario | B80: Herbolario | C80: C. Capitán Gaona, 3, 26001 Logroño, La Rioja | D80: Logroño | E80: La Rioja | F80: hierbabuenaherbolario.com | G80: 941 24 27 93 | H80: susanahierbabuena@gmail.com | I80: TRUE
A81: Catanatura | B81: Herbolario | C81: Av. Gran Vía Juan Carlos I, 41, Local, 26004 Logroño, La Rioja | D81: Logroño | E81: La Rioja | F81: catanatura.es | G81: 941 57 86 13 | H81: catanatura@catanatura.com | I81: TRUE
A82: Jacaranda Herbolario | B82: Herbolario | C82: Calle Chile, 5, 26002 Logroño, La Rioja | D82: Logroño | E82: La Rioja | F82: jacarandaherbolario.es | G82: 941 03 58 84 | H82: jacaranda821@hotmail.com | I82: TRUE
A83: Consulta De Masaje Y Osteopatía José Ángel Rodríguez | B83: Herbolario | C83: C. Siete Infantes de Lara, 16, 26007 Logroño, La Rioja | D83: Logroño | E83: La Rioja | F83: osteopatiajoseangelrodriguez.com | G83: 659 61 48 70 | H83: jangelralfaro@gmail.com | I83: TRUE
...
