Workbook

Sheet centraldecomunicacion.es
A1: ﻿Nombre | B1: Categoría | C1: Dirección | D1: Ciudad | E1: Provincia | F1: website | G1: Teléfono | H1: email | I1: mail verificado
A2: Lavandería autoservicio Almeria La Colada | B2: Lavandería de autoservicio | C2: Calle Dr. Aráez Pacheco, 16, 04004 Almería, España | D2: Almería, España | E2: España | F2: lacoladaalmeria.com | G2: +34 640 07 96 54 | H2: info@lacoladaalmeria.com | I2: =COUNTIF(Estadísticas!I:I,'centraldecomunicacion.es'!H2)>0 -> FALSE
A3: Lavandería Autoservicio Lavanda Nueva Andalucía | B3: Lavandería de autoservicio | C3: Calle Blasco Ibáñez, 34, 04006 Almería, España | D3: Almería, España | E3: España | F3: facebook.com | G3: +34 603 29 51 69 | H3: - | I3: =COUNTIF(Estadísticas!I:I,'centraldecomunicacion.es'!H3)>0 -> FALSE
A4: Lavandería autoservicio Speed Queen Almeria 2 | B4: Lavandería de autoservicio | C4: Av. de Pablo Iglesias, 27, 04003 Almería, España | D4: Almería, España | E4: España | F4: speedqueenalmeria.blogspot.com.es | I4: =COUNTIF(Estadísticas!I:I,'centraldecomunicacion.es'!H4)>0 -> FALSE
A5: Lavandería Speed Queen | B5: Lavandería de autoservicio | C5: Calle Poeta Paco Aquino, 16, 04005 Almería, España | D5: Almería, España | E5: España | F5: negocio.site | G5: +34 626 24 16 52 | H5: - | I5: =COUNTIF(Estadísticas!I:I,'centraldecomunicacion.es'!H5)>0 -> FALSE
A6: Lavandería Autoservicio Lavanda Los Ángeles | B6: Lavandería de autoservicio | C6: Calle Granada, 210, 04008 Almería, España | D6: Almería, España | E6: España | G6: +34 603 29 51 69 | H6: - | I6: =COUNTIF(Estadísticas!I:I,'centraldecomunicacion.es'!H6)>0 -> FALSE
A7: Lavandería Plaza Almería, S.L | B7: Servicio de lavandería | C7: C/Esperanza, 27 y 29 Poligono San Rafael, 04230 Huércal de Almería, Almería, España | D7: Huércal de Almería, España | E7: España | F7: lavanderiaplaza.com | G7: +34 950 14 28 88 | H7: - | I7: =COUNTIF(Estadísticas!I:I,'centraldecomunicacion.es'!H7)>0 -> FALSE
A8: Lacolada | B8: Lavandería de autoservicio | C8: Calle José Artés de Arcos, 21, 04004 Almería, España | D8: Almería, España | E8: España | H8: - | I8: =COUNTIF(Estadísticas!I:I,'centraldecomunicacion.es'!H8)>0 -> FALSE
A9: Leylaundry Lavanderia Autoservicio | B9: Lavandería de autoservicio | C9: Calle María Zambrano, 04006 Almería, España | D9: Almería, España | E9: España | H9: - | I9: =COUNTIF(Estadísticas!I:I,'centraldecomunicacion.es'!H9)>0 -> FALSE
A10: Lavomatic Almería | B10: Lavandería | C10: Av. de Cabo de Gata, 171, 04007 Almería, España | D10: Almería, España | E10: España | F10: lavomaticalmeria.es | G10: +34 630 93 20 83 | H10: - | I10: =COUNTIF(Estadísticas!I:I,'centraldecomunicacion.es'!H10)>0 -> FALSE
A11: TINTORERÍA LAVANDERÍA NIETO | B11: Lavandería | C11: Av. de Cabo de Gata, 119, 04007 Almería, España | D11: Almería, España | E11: España | F11: business.site | G11: +34 950 26 53 61 | H11: - | I11: =COUNTIF(Estadísticas!I:I,'centraldecomunicacion.es'!H11)>0 -> FALSE
A12: Lavandería Almería - Nature Lavandería | B12: Lavandería de autoservicio | C12: Calle Calz. de Castro, 36, 04006 Almería, España | D12: Almería, España | E12: España | F12: naturelavanderia.es | G12: +34 663 86 68 22 | H12: malaga@naturelavanderia.es | I12: =COUNTIF(Estadísticas!I:I,'centraldecomunicacion.es'!H12)>0 -> TRUE
A13: Lavandería y Tintorería Venezuela, S.L. | B13: Lavandería | C13: Calle San Juan Bosco, 20, 04005 Almería, España | D13: Almería, España | E13: España | G13: +34 950 26 18 70 | H13: - | I13: =COUNTIF(Estadísticas!I:I,'centraldecomunicacion.es'!H13)>0 -> FALSE
A14: Lavandería autoservicio La Abuelita | B14: Lavandería de autoservicio | C14: Calle Gustavo Villapalos, 13, 04006 Almería, España | D14: Almería, España | E14: España | F14: facebook.com | G14: +34 646 54 05 97 | H14: - | I14: =COUNTIF(Estadísticas!I:I,'centraldecomunicacion.es'!H14)>0 -> FALSE
A15: Tintorerias Adesso | B15: Tintorería | C15: Calle Lucano, 3, 04001 Almería, España | D15: Almería, España | E15: España | F15: adessotintorerias.com | G15: +34 950 95 16 37 | H15: - | I15: =COUNTIF(Estadísticas!I:I,'centraldecomunicacion.es'!H15)>0 -> FALSE
A16: New Sec Cleanner | B16: Tintorería | C16: Av. del Mediterráneo, 04007 Almería, España | D16: Almería, España | E16: España | H16: - | I16: =COUNTIF(Estadísticas!I:I,'centraldecomunicacion.es'!H16)>0 -> FALSE
A17: Lavomatic Lavandería Autoservicio | B17: Lavandería de autoservicio | C17: 04009 Almería, España | D17: Almería, España | E17: España | F17: lavomatic.es | H17: info@lavomatic.es | I17: =COUNTIF(Estadísticas!I:I,'centraldecomunicacion.es'!H17)>0 -> FALSE
A18: La Américas | B18: Tintorería | C18: Av. de Santa Isabel, 40, 04009 Almería, España | D18: Almería, España | E18: España | G18: +34 950 23 95 94 | H18: - | I18: =COUNTIF(Estadísticas!I:I,'centraldecomunicacion.es'!H18)>0 -> FALSE
A19: Tintorería Lavaclean | B19: Tintorería | C19: Calle José Artés de Arcos, 21, BAJO, 04004 Almería, España | D19: Almería, España | E19: España | F19: tintorerialavaclean.com | G19: +34 950 25 31 42 | H19: tintorerialavaclean@hotmail.com | I19: =COUNTIF(Estadísticas!I:I,'centraldecomunicacion.es'!H19)>0 -> TRUE
A20: Tintorerías Adesso S L | B20: Tintorería | C20: Av. Federico García Lorca, 40, 04004 Almería, España | D20: Almería, España | E20: España | F20: adessotintorerias.com | G20: +34 950 26 07 24 | H20: - | I20: =COUNTIF(Estadísticas!I:I,'centraldecomunicacion.es'!H20)>0 -> FALSE
A21: New Sec Cleaner | B21: Tintorería | C21: Av. del Mediterráneo, 244, 04006 Almería, España | D21: Almería, España | E21: España | G21: +34 950 22 23 29 | H21: - | I21: =COUNTIF(Estadísticas!I:I,'centraldecomunicacion.es'!H21)>0 -> FALSE
A22: Tintorerias Adesso S L | B22: Tintorería | C22: Av. del Mediterráneo, 428, 04009 Almería, España | D22: Almería, España | E22: España | F22: adessotintorerias.com | G22: +34 950 62 45 06 | H22: - | I22: =COUNTIF(Estadísticas!I:I,'centraldecomunicacion.es'!H22)>0 -> FALSE
A23: La colada de Natalia | B23: Lavandería de autoservicio | C23: Calle Alcazaba de Almeria, 32, 04230 Huércal de Almería, Almería, España | D23: Huércal de Almería, España | E23: España | G23: +34 692 56 64 25 | H23: - | I23: =COUNTIF(Estadísticas!I:I,'centraldecomunicacion.es'!H23)>0 -> FALSE
A24: Pressto | B24: Tintorería | C24: 04001 Almería, España | D24: Almería, España | E24: España | H24: - | I24: =COUNTIF(Estadísticas!I:I,'centraldecomunicacion.es'!H24)>0 -> FALSE
A25: Lavandería Mir Sl | B25: Lavandería | C25: Nº, Calle Rio Guadiana, 72, 04240 Viator, Almería, España | D25: Viator, España | E25: España | F25: lavanderiamir.com | G25: +34 950 30 43 89 | H25: lavanderiamir@lavanderiamir.com | I25: =COUNTIF(Estadísticas!I:I,'centraldecomunicacion.es'!H25)>0 -> TRUE
A26: Limpia Sec | B26: Tintorería | C26: Ctra. Campamento, 8, B, 04230 Huércal de Almería, Almería, España | D26: Huércal de Almería, España | E26: España | G26: +34 950 30 00 43 | H26: - | I26: =COUNTIF(Estadísticas!I:I,'centraldecomunicacion.es'!H26)>0 -> FALSE
A27: Limpiezas Nieto - NIETOLIMP | B27: Servicio de limpieza | C27: Av. de Santa Isabel, 88, 04009 Almería, España | D27: Almería, España | E27: España | F27: limpiezasnieto.es | G27: +34 647 41 35 79 | H27: copyright@cpanel.net | I27: =COUNTIF(Estadísticas!I:I,'centraldecomunicacion.es'!H27)>0 -> FALSE
A28: Tintoreria Ama | B28: Tintorería | C28: 04005 Almería, España | D28: Almería, España | E28: España | H28: - | I28: =COUNTIF(Estadísticas!I:I,'centraldecomunicacion.es'!H28)>0 -> FALSE
A29: Lavanderias Roquetas Kwlaqua | B29: Lavandería de autoservicio | C29: Paseo los Baños, 45, 04740 Roquetas de Mar, Almería, España | D29: Roquetas de Mar, España | E29: España | G29: +34 610 21 64 81 | H29: - | I29: =COUNTIF(Estadísticas!I:I,'centraldecomunicacion.es'!H29)>0 -> FALSE
A30: Lavanderia Autoservicio LAVAMAR | B30: Lavandería | C30: Av. Unión Europea, 64, 04740 Roquetas de Mar, Almería, España | D30: Roquetas de Mar, España | E30: España | G30: +34 629 56 42 03 | H30: - | I30: =COUNTIF(Estadísticas!I:I,'centraldecomunicacion.es'!H30)>0 -> FALSE
A31: Clothing Wash - Lavanderia | B31: Lavandería de autoservicio | C31: Bulevar Cdad. de Vicar, 614, 04738 La Gangosa, Almería, España | D31: La Gangosa, España | E31: España | G31: +34 617 48 36 81 | H31: - | I31: =COUNTIF(Estadísticas!I:I,'centraldecomunicacion.es'!H31)>0 -> FALSE
A32: Lavandería autoservicio Sweetwater | B32: Lavandería de autoservicio | C32: Av. de Carlos III, Nº 583, 04720 Aguadulce, Almería, España | D32: Aguadulce, España | E32: España | G32: +34 619 71 23 19 | H32: - | I32: =COUNTIF(Estadísticas!I:I,'centraldecomunicacion.es'!H32)>0 -> FALSE
A33: Lavanderia Rosi | B33: Lavandería | C33: Calle Julián Arcas Lacal, 5, 04740 Roquetas de Mar, Almería, España | D33: Roquetas de Mar, España | E33: España | F33: rosilimpiezaroquet.wix.com | G33: +34 950 32 07 05 | H33: - | I33: =COUNTIF(Estadísticas!I:I,'centraldecomunicacion.es'!H33)>0 -> FALSE
A34: Lacolada Roquetas Lavanderia autoservicio | B34: Lavandería de autoservicio | C34: Calle Pintor Rosales, 64, 04740 Roquetas de Mar, Almería, España | D34: Roquetas de Mar, España | E34: España | F34: facebook.com | G34: +34 950 00 23 64 | H34: - | I34: =COUNTIF(Estadísticas!I:I,'centraldecomunicacion.es'!H34)>0 -> FALSE
A35: La colada de María lavandería autoservicio | B35: Lavandería de autoservicio | C35: Calle Muluya, 17, 04740 Roquetas de Mar, Almería, España | D35: Roquetas de Mar, España | E35: España | G35: +34 642 50 66 39 | H35: - | I35: =COUNTIF(Estadísticas!I:I,'centraldecomunicacion.es'!H35)>0 -> FALSE
A36: Tendedero | B36: Lavandería de autoservicio | C36: Calle de Don Juan de Aústria, 162, 04720 Roquetas de Mar, Almería, España | D36: Roquetas de Mar, España | E36: España | F36: tendedero.negocio.site | G36: +34 658 11 89 74 | H36: - | I36: =COUNTIF(Estadísticas!I:I,'centraldecomunicacion.es'!H36)>0 -> FALSE
A37: Lavandería Speed Queen | B37: Lavandería de autoservicio | C37: Bulevar Cdad. de Vicar, 1411, 04738 Puebla de Vícar, Almería, España | D37: Puebla de Vícar, España | E37: España | F37: speedqueeninvestor.com | G37: +34 950 56 55 11 | H37: - | I37: =COUNTIF(Estadísticas!I:I,'centraldecomunicacion.es'!H37)>0 -> FALSE
A38: Lavaexpress | B38: Lavandería de autoservicio | C38: Av. las Gaviotas, 19, 04740 Roquetas de Mar, Almería, España | D38: Roquetas de Mar, España | E38: España | G38: +34 637 40 12 20 | H38: - | I38: =COUNTIF(Estadísticas!I:I,'centraldecomunicacion.es'!H38)>0 -> FALSE
A39: Lavandería autoservicio Indalo Rosa | B39: Lavandería de autoservicio | C39: Av. Europa, 161, 04745 La Mojonera, Almería, España | D39: La Mojonera, España | E39: España | G39: +34 655 17 12 09 | H39: - | I39: =COUNTIF(Estadísticas!I:I,'centraldecomunicacion.es'!H39)>0 -> FALSE
A40: LAVANDERIA CARTHAGO | B40: Lavandería | C40: Ctra. de Alicun, 356, 04721 El Parador de las Hortichuelas, Almería, España | D40: El Parador de las Hortichuelas, España | E40: España | F40: lavanderiacarthago.es | G40: +34 950 34 30 45 | H40: lavanderiacarthago@yahoo.es | I40: =COUNTIF(Estadísticas!I:I,'centraldecomunicacion.es'!H40)>0 -> FALSE
...

Sheet Estadísticas
A1: Número de empresas | B1: Número de correos electrónicos | C1: Número de webs | D1: Números de teléfono | E1: Números de teléfono fijo | F1: Números de teléfono móvil | G1: Sectores | H1: Mails únicos | I1: Mails verificados
A2: =COUNTIF('centraldecomunicacion.es'!A2:'centraldecomunicacion.es'!A19470,"*") -> 5713 | B2: =COUNTIF('centraldecomunicacion.es'!H2:'centraldecomunicacion.es'!H19470,"*@*") -> 1526 | C2: =COUNTIF('centraldecomunicacion.es'!F2:'centraldecomunicacion.es'!F19470,"*.*") -> 2940 | D2: =COUNTIF('centraldecomunicacion.es'!G2:'centraldecomunicacion.es'!G19470,"+34 6*")+COUNTIF('centraldecomunicacion.es'!G2:'centraldecomunicacion.es'!G19470,"+34 9*") -> 4606 | E2: =COUNTIF('centraldecomunicacion.es'!G2:'centraldecomunicacion.es'!G19470,"+34 9*") -> 2548 | F2: =COUNTIF('centraldecomunicacion.es'!G2:'centraldecomunicacion.es'!G19470,"+34 6*") -> 2058 | G2: {=_xlfn.UNIQUE('centraldecomunicacion.es'!B2:'centraldecomunicacion.es'!B19470)} -> Lavandería de autoservicio | H2: {=_xlfn.UNIQUE('centraldecomunicacion.es'!H2:'centraldecomunicacion.es'!H19470)} -> info@lacoladaalmeria.com | I2: malaga@naturelavanderia.es
G3: Servicio de lavandería | H3: - | I3: tintorerialavaclean@hotmail.com
G4: Lavandería | H4: 0 | I4: lavanderiamir@lavanderiamir.com
G5: Tintorería | H5: malaga@naturelavanderia.es | I5: lavamarlavanderia@gmail.com
G6: Servicio de limpieza | H6: info@lavomatic.es | I6: dcomercial@eulen.com
G7: Servicios de limpieza | H7: tintorerialavaclean@hotmail.com | I7: lavapul@gmail.com
H8: lavanderiamir@lavanderiamir.com | I8: u003einfo.lavanderia@ilunion.com
G9: Comercio | H9: copyright@cpanel.net | I9: lavanderiamedina@hotmail.es
G10: Tienda de ropa | H10: lavanderiacarthago@yahoo.es | I10: salamanca@grupofissa.com
G11: Proveedor de productos de limpieza | H11: lavamarlavanderia@gmail.com | I11: atencion@washup.es
G12: Servicio de limpieza de alfombras | H12: dcomercial@eulen.com | I12: parsi@lavanderiaindustrialparsi.es
G13: Tienda de arreglos de ropa | H13: administracion@limpiezasindalicas.com | I13: cendra@cendra-higiene.es
G14: Tienda de lavadoras y secadoras | H14: lavapul@gmail.com | I14: nes@5asec.com
G15: Servicio de limpieza de tapicería | H15: info@openwash.es | I15: ayuda@washrocks.com
G16: Organización de servicios sociales | H16: info@wasandrai.com | I16: info-china@alliancels.com
G17: Servicio de lavado a presión | H17: u003Einfo.lavanderia@ilunion.com | I17: lavanderiasclickandclean@gmail.com
G18: Tienda de lencería | H18: administracion@limpiezashurtado.com | I18: avanzamm27@gmail.com
G19: Oficinas de empresa | H19: info@nglavanderias.com | I19: tintoreriasdelfin@hotmail.com
G20: Tienda de artículos para el hogar | H20: lavanderiamedina@hotmail.es | I20: josefinazurera@hotmail.com
... G25: Tienda de productos para mascotas | H25: info@hostalcampana.es | I25: speedqueengranada@gmail.com
G26: 0 | H26: info@lacoladaweb.com | I26: tintoreriasandaluzas@gmail.com
H27: hello@ecospin.es | I27: blancolorzubia@hotmail.es
H28: hello@designbuildweb.co | I28: santafe@bloomest.es
H29: info@yonolavo.com | I29: ssanchez38@gmail.com
H30: info@coladaexpres.com | I30: surtinte@gmail.com
H31: hola@lawash.es | I31: castor@limpiezascastor.es
H32: info@dimasa.org | I32: lavanderiabloomesthuelva@bloomest.es
H33: atencion@washup.es | I33: cleanature@live.com
H34: parsi@lavanderiaindustrialparsi.es | I34: cuellar@bloomest.es
H35: info@inolav.es | I35: alicanterenfe@bloomest.es
H36: cendra@cendra-higiene.es | I36: sax@bloomest.es
H37: info@novanature.es | I37: alicantemercado@bloomest.es
H38: nes@5asec.com | I38: santomera@bloomest.es
... H274: info@perfectclean.es | I274: klin.ondarroa@gmail.com
H275: contacto@icserveis.org
H276: launderettetime@gmail.com
H277: info@lavanderiamogan.com
H278: sovereignpropertymanagement@gmail.com
H279: info@mccleancanarias.com
...

Sheet Copyright
A1: Esta base de datos de empresas se encuentra protegida bajo derechos de autor. Está prohibida su copia y reproducción con o sin ánimo de lucro bajo autorización expresa del autor según artículo 270, 270.2, 270.3, 270.4, 270.5, 270.6, 270.7 Como medida de seguridad hay registros clave a modo de firma digital registrados ante notario y ante la consejería de cultura y patrimonio histórico con número GR-00416-2020

Sheet Leads verificados
A1: ﻿Nombre | B1: Categoría | C1: Dirección | D1: Ciudad | E1: Provincia | F1: website | G1: Teléfono | H1: email | I1: mail verificado
A2: Lavandería Almería - Nature Lavandería | B2: Lavandería de autoservicio | C2: Calle Calz. de Castro, 36, 04006 Almería, España | D2: Almería, España | E2: España | F2: naturelavanderia.es | G2: +34 663 86 68 22 | H2: malaga@naturelavanderia.es | I2: TRUE
A3: Tintorería Lavaclean | B3: Tintorería | C3: Calle José Artés de Arcos, 21, BAJO, 04004 Almería, España | D3: Almería, España | E3: España | F3: tintorerialavaclean.com | G3: +34 950 25 31 42 | H3: tintorerialavaclean@hotmail.com | I3: TRUE
A4: Lavandería Mir Sl | B4: Lavandería | C4: Nº, Calle Rio Guadiana, 72, 04240 Viator, Almería, España | D4: Viator, España | E4: España | F4: lavanderiamir.com | G4: +34 950 30 43 89 | H4: lavanderiamir@lavanderiamir.com | I4: TRUE
A5: Lavandería Lavamar | B5: Servicio de lavandería | C5: Calle Dioniso, s/n, 04740 Roquetas de Mar, Almería, España | D5: Roquetas de Mar, España | E5: España | F5: lavanderialavamar.com | G5: +34 950 32 71 67 | H5: lavamarlavanderia@gmail.com | I5: TRUE
A6: Eulen | B6: Servicio de limpieza | C6: Calle Estaño, 0, 04001 Almería, España | D6: Almería, España | E6: España | F6: eulen.com | G6: +34 950 62 44 03 | H6: dcomercial@eulen.com | I6: TRUE
A7: Lavapul | B7: Lavandería | C7: Av. Estación, 29, 04649 Pulpí, Almería, España | D7: Pulpí, España | E7: España | F7: lavanderiasenlimpio.com | G7: +34 657 50 28 19 | H7: lavapul@gmail.com | I7: TRUE
A8: ILUNION | B8: Lavandería | C8: Polígono Industrial Zona Franca, Calle San Roque, s/n, 11006 Cádiz, España | D8: Cádiz, España | E8: España | F8: lavanderia.ilunion.com | G8: +34 956 28 41 46 | H8: u003Einfo.lavanderia@ilunion.com | I8: TRUE
A9: Lavanderia Medina | B9: Lavandería | C9: Arroyo de Galbarro,, Cádiz, España | D9: Medina-Sidonia, España | E9: España | F9: lavanderiamedina.es | G9: +34 956 42 33 97 | H9: lavanderiamedina@hotmail.es | I9: TRUE
A10: Fissa Cádiz | B10: Servicios de limpieza | C10: Calle Viento del Sur, 6, 11100 San Fernando, Cádiz, España | D10: San Fernando, España | E10: España | F10: grupofissa.com | G10: +34 956 59 70 20 | H10: salamanca@grupofissa.com | I10: TRUE
A11: Wash-up - Huelin - Lavandería Autoservicio | B11: Lavandería de autoservicio | C11: Calle Infantes, 37, 29002 Málaga, España | D11: Málaga, España | E11: España | F11: washup.es | G11: +34 689 91 77 78 | H11: atencion@washup.es | I11: TRUE
A12: Parsi Lavandería Industrial | B12: Lavandería | C12: Calle Parsi 6, nº 44, 41016 Sevilla, España | D12: Sevilla, España | E12: España | F12: lavanderiaindustrialparsi.es | G12: +34 669 76 34 38 | H12: parsi@lavanderiaindustrialparsi.es | I12: TRUE
A13: Cendra | B13: Servicio de lavandería | C13: Calle Almonte, 10, 29004 Málaga, España | D13: Málaga, España | E13: España | F13: cendra-higiene.es | G13: +34 951 13 93 63 | H13: cendra@cendra-higiene.es | I13: TRUE
A14: Tintorería 5àsec | B14: Tintorería | C14: Calle Río, 3, 29002 Málaga, España | D14: Málaga, España | E14: España | F14: 5asec.es | G14: +34 952 34 34 86 | H14: nes@5asec.com | I14: TRUE
A15: Washrocks - APP de Tintorería a domicilio | B15: Tintorería | D15: Alcalá de los Gazules | F15: washrocks.com | G15: +34 654 27 51 62 | H15: ayuda@washrocks.com | I15: TRUE
A16: Alliance Laundry Systems Spain S L | B16: Lavandería de autoservicio | C16: Carrer del Solsonès, 2, 08820 El Prat de Llobregat, Barcelona, España | D16: El Prat de Llobregat, España | E16: España | F16: alliancelaundry.es | G16: +34 934 79 54 10 | H16: info-China@alliancels.com | I16: TRUE
A17: Click And Clean - Lavandería Autoservicio - Córdoba | B17: Lavandería | C17: Calle Ronda de la Manca, 4, 14010 Córdoba, España | D17: Córdoba, España | E17: España | F17: lavanderiasclickandclean.es | G17: +34 623 41 51 94 | H17: lavanderiasclickandclean@gmail.com | I17: TRUE
A18: Lavanderia Avanza | B18: Tintorería | C18: Pol. Ind. Pedroches, Calle los Metalúrgicos, 66, 14014 Córdoba, España | D18: Córdoba, España | E18: España | F18: lavanderiaavanza.com | G18: +34 606 23 87 87 | H18: avanzamm27@gmail.com | I18: TRUE
A19: Tintorerías Damasco y Coral | B19: Tintorería | C19: Calle el Almendro, 3, 14006 Córdoba, España | D19: Córdoba, España | E19: España | F19: tintoreriacoralcordoba.es | G19: +34 957 27 20 09 | H19: tintoreriasdelfin@hotmail.com | I19: TRUE
A20: Tintorería en Córdoba | Higiensec | B20: Tintorería | C20: Calle Felipe II, 15, 14005 Córdoba, España | D20: Córdoba, España | E20: España | F20: tintoreria-cordoba.es | G20: +34 957 41 17 44 | H20: josefinazurera@hotmail.com | I20: TRUE
A21: Hilo y Plancha | B21: Lavandería | C21: Calle Ángel de Saavedra, 2, 14003 Córdoba, España | D21: Córdoba, España | E21: España | F21: hiloyplancha.es | G21: +34 957 48 52 51 | H21: t.villena@hiloyplancha.es | I21: TRUE
A22: Empresas Limpieza | Brillo Expres | B22: Servicios de limpieza | C22: Calle Betis, 31 - Local 1, 14011 Córdoba, España | D22: Córdoba, España | E22: España | F22: brilloexpres.com | G22: +34 957 76 77 24 | H22: brilloexpres@brilloexpres.com | I22: TRUE
A23: Lavandería Industrial Rubio S.R.L | B23: Lavandería | C23: Polígono Industrial Quintos, 3 Parcela, 14193 Fontanar de Quintos, España | D23: Fontanar de Quintos, España | E23: España | F23: cplavanderiarubio.jimdo.com | G23: +34 957 32 45 81 | H23: lavanderiaindustrialrubio@gmail.com | I23: TRUE
A24: Centro de Limpieza Hermanos Espinar López S.L. | B24: Lavandería | C24: Calle el Batán, 14816 Zagrilla Baja, Córdoba, España | D24: Zagrilla Baja, España | E24: España | F24: limpiezaespinarlopez.com | G24: +34 651 84 43 22 | H24: limpiezaespinarlopez@hotmail.com | I24: TRUE
A25: Lavandería Autoservicio Granada Speed Queen-4ECO (Limpieza a Granel) | B25: Lavandería de autoservicio | C25: Calle Acera de Canasteros, 2, 18001 Granada, España | D25: Granada, España | E25: España | F25: lavanderiasgranada.com | G25: +34 667 45 62 10 | H25: speedqueengranada@gmail.com | I25: TRUE
A26: Tintorerias Andaluzas | B26: Tintorería | C26: Calle Real, 9, 18200 Maracena, Granada, España | D26: Maracena, España | E26: España | F26: tintoreriasandaluzas.com | G26: +34 633 41 97 01 | H26: tintoreriasandaluzas@gmail.com | I26: TRUE
A27: TINTORERÍA LA ZUBIA | B27: Tintorería | C27: Calle Cerezo, 10, 18140 La Zubia, Granada, España | D27: La Zubia, España | E27: España | F27: lavanderiablancolor.com | G27: +34 958 89 06 56 | H27: blancolorzubia@hotmail.es | I27: TRUE
... A99: LavanderiaAzul Lavandería Autoservicio Adeje | TheBlueLaundry Self Service Laundry | B99: Lavandería de autoservicio | C99: Av. de la Constitución, 45, 38670 Adeje, Santa Cruz de Tenerife, España | D99: Adeje, España | E99: España | F99: lavanderiaazul.es | G99: +34 661 13 59 96 | H99: lavanderiaautolavado@gmail.com | I99: TRUE
A100: La Lavandería | B100: Servicio de lavandería | D100: Adeje | F100: lalavanderiasur.com | G100: +34 699 81 17 15 | H100: lalavanderiasur@gmail.com | I100: TRUE
A101: Santander Lavanderia Industrial | B101: Tintorería | C101: Calle el Somo, 56, 39012 Santander, Cantabria, España | D101: Santander, España | E101: España | F101: santanderlavanderiaindustrial.com | G101: +34 685 91 01 57 | H101: santanderlavanderiaindustrial@gmail.com | I101: TRUE
A102: TINTORERIA LAVANDERIA Y ARREGLOS MALLABIA | B102: Tintorería | C102: Gernikako Arbola Etorbidea, 36, 48902 Barakaldo, Bizkaia, España | D102: Baracaldo, España | E102: España | F102: tintoreriamallabia.com | G102: +34 944 37 21 00 | H102: tintomallabia@gmail.com | I102: TRUE
A103: LAYFIL,S.L. | B103: Lavandería | C103: 48810 Alonsotegi, BI, España | D103: Alonsótegui, España | E103: España | F103: layfil.com | G103: +34 944 86 01 33 | H103: layfil@layfil.com | I103: TRUE
A104: Lavanindu S.L. | B104: Lavandería | C104: Barrio de Martiartu, 18, 48480 Martiartu, BI, España | D104: Martiartu, España | E104: España | F104: lavanindu.es | G104: +34 946 71 39 11 | H104: lavanindu@lavanindu.es | I104: TRUE
A105: Lavandería Limcos Burgos | B105: Lavandería | C105: Calle Los Rompizales, 5, 09001 Burgos, España | D105: Burgos, España | E105: España | F105: grupolimcos.es | G105: +34 947 20 48 71 | H105: limcosburgos@gmail.com | I105: TRUE
A106: Tintorería - Lavandería Garbiñe | B106: Lavandería de autoservicio | C106: Gorbea Kalea, 46, BJ, 01012 Gasteiz, Araba, España | D106: Vitoria-Gasteiz, España | E106: España | F106: tintoreriagarbine.com | G106: +34 945 24 88 48 | H106: tintegarbine@gmail.com | I106: TRUE
A107: Albalimp | B107: Servicios de limpieza | C107: Calle Antonio Gotor, 7, 02002 Albacete, España | D107: Albacete, España | E107: España | F107: albalimp.com | G107: +34 967 50 41 97 | H107: limpieza@albalimp.com | I107: TRUE
A108: TINTORERIA APRESTO | B108: Tintorería | C108: Calle Padres Capuchinos, 8, 13200 Manzanares, Cdad. Real, España | D108: Manzanares, España | E108: España | F108: tintoreriarapidaydecalidad.es | G108: +34 926 61 15 45 | H108: ifernandez@padellasede.com | I108: TRUE
A109: Lavandería autoservicio Bloomest en Campo de Criptana | B109: Lavandería de autoservicio | C109: Calle Isaac Peral, 38, 13610 Campo de Criptana, Cdad. Real, España | D109: Campo de Criptana, España | E109: España | F109: campodecriptana.bloomest.es | G109: +34 634 54 60 85 | H109: campodecriptana@bloomest.es | I109: TRUE
A110: Lavandería Autoservicio Bloomest en Alcorcón | B110: Lavandería de autoservicio | C110: Paseo Castilla, 3, 28921 Alcorcón, Madrid, España | D110: Alcorcón, España | E110: España | F110: alcorcon.bloomest.es | G110: +34 628 33 74 64 | H110: alcorcon@bloomest.es | I110: TRUE
A111: Lavanderia Autoservicio Bloomest Leganés | B111: Lavandería de autoservicio | C111: Plaza Hernán Cortés, 4, 28911 Leganés, Madrid, España | D111: Leganés, España | E111: España | F111: leganes.bloomest.es | G111: +34 640 83 12 74 | H111: leganes@bloomest.es | I111: TRUE
...
