Workbook

Sheet Canteras
A1: ﻿Nombre | B1: Categoría | C1: Rating | D1: Nº Reviews | E1: Horario | F1: Código Plus | G1: Direccion | H1: Localidad | I1: Provincia | J1: Website | K1: Teléfono | L1: email | M1: Reclamar | N1: Latitud | O1: Longitud | P1: Url en Maps | Q1: Iframe | R1: Imagen Url
A2: Mina de Talco | B2: Mina | C2: 4,7 | D2: 3 | E2: viernes, Abierto 24 horas; sábado, Abierto 24 horas; domingo, Abierto 24 horas; lunes, Abierto 24 horas; martes, Abierto 24 horas; miércoles, Abierto 24 horas; jueves, Abierto 24 horas | F2: VG3C+9W Almería | G2: Acceso a A-7, 04008 Almería | H2: Almería | I2: Almería | L2: - | M2: Sí | N2: 36.8534497 | O2: -2.4776319 | P2: https://goo.gl/maps/H7zr6KFoZGtTPcYe8 | Q2: <iframe src="https://www.google.com/maps/embed?pb=!1m18!1m12!1m3!1d102177.29575124479!2d-2.5096470540265146!3d36.84150627352816!2m3!1f0!2f0!3f0!3m2!1i1024!2i768!4f13.1!3m3!1m2!1s0xd7075e3c8d5c031%3A0xb3a18684c09ff2ed!2sMina%20de%20Talco!5e0!3m2!1ses!2ses!4v1651828762041!5m2!1ses!2ses" width="600" height="450" style="border:0;" allowfullscreen="" loading="lazy" referrerpolicy="no-referrer-when-downgrade"></iframe> | R2: https://lh5.googleusercontent.com/p/AF1QipNYA_-JNgsH10SzKiBpJER4nVp8QOnuUIR-QQmX=w408-h544-k-no
A3: Instituto Geologico Y Minero De España | B3: Oficina de gobierno local | F3: RGPM+C9 Almería | G3: C. Real, 115, 04002 Almería | H3: Almería | I3: Almería | K3: 950 25 11 66 | L3: - | M3: Sí | N3: 36.836107 | O3: -2.4666197 | P3: https://goo.gl/maps/s5APDuVoixjdzfCm9 | Q3: <iframe src="https://www.google.com/maps/embed?pb=!1m18!1m12!1m3!1d102177.29575124479!2d-2.5096470540265146!3d36.84150627352816!2m3!1f0!2f0!3f0!3m2!1i1024!2i768!4f13.1!3m3!1m2!1s0xd7076043e130c4d%3A0xbe8908974fb212c8!2sInstituto%20Geologico%20Y%20Minero%20De%20Espa%C3%B1a!5e0!3m2!1ses!2ses!4v1651828770778!5m2!1ses!2ses" width="600" height="450" style="border:0;" allowfullscreen="" loading="lazy" referrerpolicy="no-referrer-when-downgrade"></iframe> | R3: https://streetviewpixels-pa.googleapis.com/v1/thumbnail?panoid=VyhU0bYhaHdxzEqojEztsw&cb_client=search.gws-prod.gps&w=408&h=240&yaw=133.7938&pitch=0&thumbfov=100
A4: Minas De Rodalquilar | B4: Mina | C4: 4,3 | D4: 108 | E4: viernes, Abierto 24 horas; sábado, Abierto 24 horas; domingo, Abierto 24 horas; lunes, Abierto 24 horas; martes, Abierto 24 horas; miércoles, Abierto 24 horas; jueves, Abierto 24 horas | F4: VX33+87 Níjar | G4: C. Apartadero, 9, 04115 Níjar, Almería | H4: Níjar | I4: Almería | L4: - | M4: Sí | N4: 36.8532568 | O4: -2.0467748 | P4: https://goo.gl/maps/SD9PnMMPdjKsf6qAA | Q4: <iframe src="https://www.google.com/maps/embed?pb=!1m18!1m12!1m3!1d102161.5935192764!2d-2.1168126417968627!3d36.853256800000004!2m3!1f0!2f0!3f0!3m2!1i1024!2i768!4f13.1!3m3!1m2!1s0xd7ae953d0696c25%3A0x8a62f495a746f766!2sMinas%20De%20Rodalquilar!5e0!3m2!1ses!2ses!4v1651828776746!5m2!1ses!2ses" width="600" height="450" style="border:0;" allowfullscreen="" loading="lazy" referrerpolicy="no-referrer-when-downgrade"></iframe> | R4: https://lh5.googleusercontent.com/p/AF1QipM7JNxYV8MiPi3HM41YePyLgqPUWbAgqo8XW1CK=w426-h240-k-no
A5: Minas de La Partala | B5: Lugar de interés histórico | C5: 5,0 | D5: 2 | F5: WG9C+RC Benahadux | G5: 04410 Benahadux, Almería | H5: Benahadux | I5: Almería | L5: - | M5: Sí | N5: 36.9196174 | O5: -2.4789464 | P5: https://goo.gl/maps/SmUHY1fFsZWVYxPk8 | Q5: <iframe src="https://www.google.com/maps/embed?pb=!1m18!1m12!1m3!1d102072.83519346103!2d-2.5489842417968744!3d36.91961739999999!2m3!1f0!2f0!3f0!3m2!1i1024!2i768!4f13.1!3m3!1m2!1s0xd70759b1e56f223%3A0x8b8797f288f78fbf!2sMinas%20de%20La%20Partala!5e0!3m2!1ses!2ses!4v1651828782527!5m2!1ses!2ses" width="600" height="450" style="border:0;" allowfullscreen="" loading="lazy" referrerpolicy="no-referrer-when-downgrade"></iframe> | R5: https://lh5.googleusercontent.com/p/AF1QipOs0wJod4bzUqg84etBq1bUn7o0tW1VFa8Lsx1D=w408-h541-k-no
A6: Minas del Carmen | B6: Mina | C6: 4,0 | D6: 4 | F6: V9P9+WX El Marchal de Antón López | G6: Barranco de Plateros, 04729 El Marchal de Antón López, Almería | H6: El Marchal de Antón López | I6: Almería | L6: - | M6: Sí | N6: 36.8872855 | O6: -2.6301245 | P6: https://goo.gl/maps/zfidVebut4PraLzH7 | Q6: <iframe src="https://www.google.com/maps/embed?pb=!1m18!1m12!1m3!1d102116.09672020565!2d-2.700162341796924!3d36.88728550000001!2m3!1f0!2f0!3f0!3m2!1i1024!2i768!4f13.1!3m3!1m2!1s0xd706d77358504af%3A0x37b9100bdcc479e!2sMinas%20del%20Carmen!5e0!3m2!1ses!2ses!4v1651828788372!5m2!1ses!2ses" width="600" height="450" style="border:0;" allowfullscreen="" loading="lazy" referrerpolicy="no-referrer-when-downgrade"></iframe> | R6: https://lh5.googleusercontent.com/p/AF1QipPwoDRQBuprdGz2YFbXC241WUL55fdjpLrXuSV9=w408-h663-k-no
A7: Coto Láisquez | B7: Mina | C7: 5,0 | D7: 1 | F7: XPPW+R2 Huebro | G7: 04119, Almería | H7: Huebro | I7: Almería | L7: - | M7: Sí | N7: 36.9870472 | O7: -2.2549732 | P7: https://goo.gl/maps/WWaxpbBjMZybCnaB7 | Q7: <iframe src="https://www.google.com/maps/embed?pb=!1m18!1m12!1m3!1d101982.50654396469!2d-2.325011041796891!3d36.98704719999999!2m3!1f0!2f0!3f0!3m2!1i1024!2i768!4f13.1!3m3!1m2!1s0xd7abc5a9ac3a90d%3A0xf7da6cb6cc27f67!2sCoto%20L%C3%A1isquez!5e0!3m2!1ses!2ses!4v1651828795700!5m2!1ses!2ses" width="600" height="450" style="border:0;" allowfullscreen="" loading="lazy" referrerpolicy="no-referrer-when-downgrade"></iframe> | R7: https://lh5.googleusercontent.com/p/AF1QipMYoUFQJt3hJsAjeZV-P92PkECTwivwkSYagNmG=w408-h306-k-no
A8: Ingeniera Técnica Minera Fadrique | B8: Ingeniero de minas | E8: viernes, De 7:00 a 20:00; sábado, De 7:00 a 14:00; domingo, Cerrado; lunes, De 7:00 a 20:00; martes, De 7:00 a 20:00; miércoles, De 7:00 a 20:00; jueves, De 7:00 a 20:00 | F8: R9MQ+9C La Envía | G8: Calle de los Nogales, 25, 04727 La Envía, Almería | H8: La Envía | I8: Almería | K8: 655 64 34 85 | L8: - | M8: No | N8: 36.8333937 | O8: -2.6114838 | P8: https://goo.gl/maps/KxMmiMVJdCop3rMB9 | Q8: <iframe src="https://www.google.com/maps/embed?pb=!1m18!1m12!1m3!1d102188.12606272443!2d-2.681470341796881!3d36.833399700000015!2m3!1f0!2f0!3f0!3m2!1i1024!2i768!4f13.1!3m3!1m2!1s0xd707114dd75b5f1%3A0x56f1858ef64cd51e!2sIngeniera%20T%C3%A9cnica%20Minera%20Fadrique!5e0!3m2!1ses!2ses!4v1651828801903!5m2!1ses!2ses" width="600" height="450" style="border:0;" allowfullscreen="" loading="lazy" referrerpolicy="no-referrer-when-downgrade"></iframe>
A9: Poblado minero de San Diego | B9: Mina | C9: 4,7 | D9: 9 | E9: viernes, Abierto 24 horas; sábado, Abierto 24 horas; domingo, Abierto 24 horas; lunes, Abierto 24 horas; martes, Abierto 24 horas; miércoles, Abierto 24 horas; jueves, Abierto 24 horas | F9: RWXM+7W Níjar | G9: 04115 Níjar, Almería | H9: Níjar | I9: Almería | L9: - | M9: Sí | N9: 36.84815 | O9: -2.0651921 | P9: https://goo.gl/maps/D7BfbL3PA9u6PSAk9 | Q9: <iframe src="https://www.google.com/maps/embed?pb=!1m18!1m12!1m3!1d102168.41826557778!2d-2.1352299417968745!3d36.84815000000001!2m3!1f0!2f0!3f0!3m2!1i1024!2i768!4f13.1!3m3!1m2!1s0xd7aeeaaf2909097%3A0x386f3f166850bbf8!2sPoblado%20minero%20de%20San%20Diego!5e0!3m2!1ses!2ses!4v1651828809200!5m2!1ses!2ses" width="600" height="450" style="border:0;" allowfullscreen="" loading="lazy" referrerpolicy="no-referrer-when-downgrade"></iframe> | R9: https://lh5.googleusercontent.com/p/AF1QipO09354IuIgbGZU2eDfYwYEx4EyVn2WhgWSMCh3=w408-h306-k-no
A10: Mina Felisa | B10: Zona de senderismo | E10: viernes, Abierto 24 horas; sábado, Abierto 24 horas; domingo, Abierto 24 horas; lunes, Abierto 24 horas; martes, Abierto 24 horas; miércoles, Abierto 24 horas; jueves, Abierto 24 horas | F10: XHHF+77 Rioja | G10: 04260 Rioja, Almería | H10: Rioja | I10: Almería | L10: - | M10: Sí | N10: 36.9782066 | O10: -2.4267534 | P10: https://goo.gl/maps/Y5wNWRgPgevQFJuy5 | Q10: <iframe src="https://www.google.com/maps/embed?pb=!1m18!1m12!1m3!1d101994.35741913112!2d-2.496791241796892!3d36.97820660000001!2m3!1f0!2f0!3f0!3m2!1i1024!2i768!4f13.1!3m3!1m2!1s0xd7aa1efb46fc53d%3A0x1bc8cfa011f2779f!2sMina%20Felisa!5e0!3m2!1ses!2ses!4v1651828815684!5m2!1ses!2ses" width="600" height="450" style="border:0;" allowfullscreen="" loading="lazy" referrerpolicy="no-referrer-when-downgrade"></iframe> | R10: https://lh5.googleusercontent.com/p/AF1QipNwOCS-JHDjZfmfJ-6f6QHAXrT3hoKVMn8ziDJV=w408-h306-k-no
A11: COMISUR COMPAÑIAS MINERAS DEL SUR S.A. | B11: Empresa minera | F11: 8MMX+M8 Macael | G11: Av. Almería, 21, 04867 Macael, Almería | H11: Macael | I11: Almería | K11: 950 12 88 34 | L11: - | M11: No | N11: 37.3342412 | O11: -2.3016892 | P11: https://goo.gl/maps/5WygwnVrhBAre5YD8 | Q11: <iframe src="https://www.google.com/maps/embed?pb=!1m18!1m12!1m3!1d101515.173781624!2d-2.3717270417968748!3d37.334241200000015!2m3!1f0!2f0!3f0!3m2!1i1024!2i768!4f13.1!3m3!1m2!1s0xd654d04830d5cf1%3A0x600cf9e3fe2978!2sCOMISUR%20COMPA%C3%91IAS%20MINERAS%20DEL%20SUR%20S.A.!5e0!3m2!1ses!2ses!4v1651828821856!5m2!1ses!2ses" width="600" height="450" style="border:0;" allowfullscreen="" loading="lazy" referrerpolicy="no-referrer-when-downgrade"></iframe> | R11: https://streetviewpixels-pa.googleapis.com/v1/thumbnail?panoid=AtJ6xYJe92dlU4Okf9_5gA&cb_client=search.gws-prod.gps&w=408&h=240&yaw=341.44754&pitch=0&thumbfov=100
A12: Hornos de calcinación | B12: Museo | C12: 4,4 | D12: 211 | E12: viernes, Abierto 24 horas; sábado, Abierto 24 horas; domingo, Abierto 24 horas; lunes, Abierto 24 horas; martes, Abierto 24 horas; miércoles, Abierto 24 horas; jueves, Abierto 24 horas | F12: 2QRQ+43 Lucainena de las Torres | G12: 04210 Lucainena de las Torres, Almería | H12: Lucainena de las Torres | I12: Almería | K12: 950 36 30 71 | L12: - | M12: Sí | N12: 37.040343 | O12: -2.2122642 | P12: https://goo.gl/maps/WnrR8ztznt4wtdBE8 | Q12: <iframe src="https://www.google.com/maps/embed?pb=!1m18!1m12!1m3!1d101911.01178879624!2d-2.282302041796875!3d37.04034299999999!2m3!1f0!2f0!3f0!3m2!1i1024!2i768!4f13.1!3m3!1m2!1s0xd7ab9429a1bb43b%3A0x3cec3ea2160950f3!2sHornos%20de%20calcinaci%C3%B3n!5e0!3m2!1ses!2ses!4v1651828828966!5m2!1ses!2ses" width="600" height="450" style="border:0;" allowfullscreen="" loading="lazy" referrerpolicy="no-referrer-when-downgrade"></iframe> | R12: https://lh5.googleusercontent.com/p/AF1QipMAjIT8oMCLRrD0AjgCihCh7vbC2HqHRRyuji08=w408-h306-k-no
A13: Las Menas poblado minero | B13: Lugar de interés histórico | C13: 4,3 | D13: 19 | F13: 7FMR+GF Serón | G13: 04897 Serón, Almería | H13: Serón | I13: Almería | J13: turismoseron.es | L13: info@turismoseron.es | M13: Sí | N13: 37.2837955 | O13: -2.5088387 | P13: https://goo.gl/maps/v4uWqBUEYe7z9ssv9 | Q13: <iframe src="https://www.google.com/maps/embed?pb=!1m18!1m12!1m3!1d101583.30695762283!2d-2.5788765417968746!3d37.28379549999998!2m3!1f0!2f0!3f0!3m2!1i1024!2i768!4f13.1!3m3!1m2!1s0xd6fff4c0b1d9edb%3A0x9a749ea8bcf64cd0!2sLas%20Menas%20poblado%20minero!5e0!3m2!1ses!2ses!4v1651828843215!5m2!1ses!2ses" width="600" height="450" style="border:0;" allowfullscreen="" loading="lazy" referrerpolicy="no-referrer-when-downgrade"></iframe> | R13: https://lh5.googleusercontent.com/p/AF1QipNsrk5I9WZNglbVetmgqi8jnI_izfWxtmvYr6Sv=w408-h271-k-no
A14: Monumento al minero | B14: Parque | C14: 4,6 | D14: 22 | E14: viernes, Abierto 24 horas; sábado, Abierto 24 horas; domingo, Abierto 24 horas; lunes, Abierto 24 horas; martes, Abierto 24 horas; miércoles, Abierto 24 horas; jueves, Abierto 24 horas | F14: X4JV+6F Fondón | G14: 04460 Fondón, Almería | H14: Fondón | I14: Almería | L14: - | M14: Sí | N14: 36.9805923 | O14: -2.8563226 | P14: https://goo.gl/maps/ZwKtyt9kc1zXyTu26 | Q14: <iframe src="https://www.google.com/maps/embed?pb=!1m18!1m12!1m3!1d101991.15961376754!2d-2.926360441796875!3d36.980592299999984!2m3!1f0!2f0!3f0!3m2!1i1024!2i768!4f13.1!3m3!1m2!1s0xd703fa88c9e6aa5%3A0xa5fdc0b20e50b9d9!2sMonumento%20al%20minero!5e0!3m2!1ses!2ses!4v1651828856512!5m2!1ses!2ses" width="600" height="450" style="border:0;" allowfullscreen="" loading="lazy" referrerpolicy="no-referrer-when-downgrade"></iframe> | R14: https://lh5.googleusercontent.com/p/AF1QipMbazg4gNgEpO03rWgWkxpHD__FgdiEb1PgOGsi=w408-h306-k-no
A15: Bitmineros | B15: Equipo para minería | C15: 5,0 | D15: 7 | E15: viernes, De 9:00 a 17:00; sábado, Cerrado; domingo, Cerrado; lunes, De 9:00 a 17:00; martes, De 9:00 a 17:00; miércoles, De 9:00 a 17:00; jueves, De 9:00 a 17:00 | F15: Q9GR+43 Roquetas de Mar | G15: C. Lugo, 12, puerta 4, 04740 Roquetas de Mar, Almería | H15: Roquetas de Mar | I15: Almería | J15: bitmineros.net | K15: 672 01 20 05 | L15: core-js-bundle@3.2.1 | M15: No | N15: 36.7753057 | O15: -2.6098554 | P15: https://goo.gl/maps/M4nSq51M7SB843jE8 | Q15: <iframe src="https://www.google.com/maps/embed?pb=!1m18!1m12!1m3!1d102265.6855392626!2d-2.6798951417968664!3d36.775301!2m3!1f0!2f0!3f0!3m2!1i1024!2i768!4f13.1!3m3!1m2!1s0xd7071d06732952f%3A0xafe2f126298786d6!2sBitmineros!5e0!3m2!1ses!2ses!4v1651828864231!5m2!1ses!2ses" width="600" height="450" style="border:0;" allowfullscreen="" loading="lazy" referrerpolicy="no-referrer-when-downgrade"></iframe> | R15: https://lh5.googleusercontent.com/p/AF1QipM-GNrNlKv3K4PRpFm0JEOsRjzU_f7IJyakIIER=w408-h333-k-no
A16: Poblado Minero El Arteal | B16: Lugar de interés histórico | C16: 3,8 | D16: 16 | E16: viernes, Abierto 24 horas; sábado, Abierto 24 horas; domingo, Abierto 24 horas; lunes, Abierto 24 horas; martes, Abierto 24 horas; miércoles, Abierto 24 horas; jueves, Abierto 24 horas | F16: 76C9+PC El Arteal | G16: Unnamed Road, 04618, Almería | H16: El Arteal | I16: Almería | L16: - | M16: Sí | N16: 37.2717802 | O16: -1.7814317 | P16: https://goo.gl/maps/1joQjeRWa7dbnkRDA | Q16: <iframe src="https://www.google.com/maps/embed?pb=!1m18!1m12!1m3!1d101599.52350127177!2d-1.8514695417968752!3d37.27178020000001!2m3!1f0!2f0!3f0!3m2!1i1024!2i768!4f13.1!3m3!1m2!1s0xd7b2b889fe46bc7%3A0x3df4b2950223e484!2sPoblado%20Minero%20El%20Arteal!5e0!3m2!1ses!2ses!4v1651828870402!5m2!1ses!2ses" width="600" height="450" style="border:0;" allowfullscreen="" loading="lazy" referrerpolicy="no-referrer-when-downgrade"></iframe> | R16: https://lh5.googleusercontent.com/p/AF1QipP4OXw1pkmp-Hct5DGS7DHUwdwz8ELWOEwXAfSu=w426-h240-k-no
A17: Monumento a la Mineria | B17: Museo | C17: 4,5 | D17: 2 | F17: 7FMQ+8J Serón | G17: 04897 Serón, Almería | H17: Serón | I17: Almería | L17: - | M17: Sí | N17: 37.2833103 | O17: -2.5109057 | P17: https://goo.gl/maps/b3LAWYVp5FmT5LyA6 | Q17: <iframe src="https://www.google.com/maps/embed?pb=!1m18!1m12!1m3!1d101583.9618981604!2d-2.580943541796875!3d37.283310300000004!2m3!1f0!2f0!3f0!3m2!1i1024!2i768!4f13.1!3m3!1m2!1s0xd6ffe3a8da6cab1%3A0xa43339deece9f8c4!2sMonumento%20a%20la%20Mineria!5e0!3m2!1ses!2ses!4v1651828876714!5m2!1ses!2ses" width="600" height="450" style="border:0;" allowfullscreen="" loading="lazy" referrerpolicy="no-referrer-when-downgrade"></iframe> | R17: https://lh5.googleusercontent.com/p/AF1QipPGQFN70KW_6J6O6RBdVEW6pX_hlMK1XVYAH7qc=w408-h306-k-no
A18: Minera De Orgiva S L | B18: Empresa minera | C18: 4,0 | D18: 2 | F18: WH2J+P7 Órgiva | G18: C. Almeria, 8, 18400 Órgiva, Granada | H18: Órgiva | I18: Granada | K18: 858 78 40 58 | L18: - | M18: Sí | N18: 36.90176 | O18: -3.4193022 | P18: https://goo.gl/maps/VdJJBQKJ186iyYro7 | Q18: <iframe src="https://www.google.com/maps/embed?pb=!1m18!1m12!1m3!1d102096.73321181926!2d-3.489347841796875!3d36.90175999999998!2m3!1f0!2f0!3f0!3m2!1i1024!2i768!4f13.1!3m3!1m2!1s0xd71bffe28f5a17f%3A0x4ae3cd8f325c317c!2sMinera%20De%20Orgiva%20S%20L!5e0!3m2!1ses!2ses!4v1651828882792!5m2!1ses!2ses" width="600" height="450" style="border:0;" allowfullscreen="" loading="lazy" referrerpolicy="no-referrer-when-downgrade"></iframe> | R18: https://lh5.googleusercontent.com/p/AF1QipN4tY5c2pF41fVVqE2hJlvDWvPYCbMdKxYTiQdJ=w426-h240-k-no
A19: Poblado minero ruinas Rodalquilar | B19: Lugar de interés histórico | C19: 3,4 | D19: 5 | E19: viernes, Abierto 24 horas; sábado, Abierto 24 horas; domingo, Abierto 24 horas; lunes, Abierto 24 horas; martes, Abierto 24 horas; miércoles, Abierto 24 horas; jueves, Abierto 24 horas | F19: RXW4+5Q Rodalquilar | G19: C. Villa Cepillo, 97, 04115 Rodalquilar, Almería | H19: Rodalquilar | I19: Almería | L19: - | M19: Sí | N19: 36.8454564 | O19: -2.0430272 | P19: https://goo.gl/maps/iLDef4deToM5pqzy6 | Q19: <iframe src="https://www.google.com/maps/embed?pb=!1m18!1m12!1m3!1d102172.01767557008!2d-2.1130650417968746!3d36.84545639999998!2m3!1f0!2f0!3f0!3m2!1i1024!2i768!4f13.1!3m3!1m2!1s0xd7aefeacd8e8d73%3A0xe3a9ce2ad0ae5e99!2sPoblado%20minero%20ruinas%20Rodalquilar!5e0!3m2!1ses!2ses!4v1651828888934!5m2!1ses!2ses" width="600" height="450" style="border:0;" allowfullscreen="" loading="lazy" referrerpolicy="no-referrer-when-downgrade"></iframe> | R19: https://lh5.googleusercontent.com/p/AF1QipOgMCKJi3obldJlNci0402XKtQCgsevmrESh4mz=w426-h240-k-no
A20: Paseo de la fama de Almería | B20: Lugar de interés histórico | C20: 4,2 | D20: 419 | E20: viernes, Abierto 24 horas; sábado, Abierto 24 horas; domingo, Abierto 24 horas; lunes, Abierto 24 horas; martes, Abierto 24 horas; miércoles, Abierto 24 horas; jueves, Abierto 24 horas | F20: RGPP+WJ Almería | G20: C. Poeta Villaespesa, 2, 04001 Almería | H20: Almería | I20: Almería | K20: 950 21 00 00 | L20: - | M20: Sí | N20: 36.8373313 | O20: -2.4634543 | P20: https://goo.gl/maps/dkopgQjVQTdobwaK7 | Q20: <iframe src="https://www.google.com/maps/embed?pb=!1m18!1m12!1m3!1d25545.718433725233!2d-2.4809637604492187!3d36.837331299999995!2m3!1f0!2f0!3f0!3m2!1i1024!2i768!4f13.1!3m3!1m2!1s0xd7076017d445ab7%3A0x2c051c67fe2dfa80!2sPaseo%20de%20la%20fama%20de%20Almer%C3%ADa!5e0!3m2!1ses!2ses!4v1651828924294!5m2!1ses!2ses" width="600" height="450" style="border:0;" allowfullscreen="" loading="lazy" referrerpolicy="no-referrer-when-downgrade"></iframe> | R20: https://lh5.googleusercontent.com/p/AF1QipOjZA0_XokWR6KWs7fE7bQn9sx3cPmhjOd0dWZq=w408-h544-k-no
A21: Segura | B21: Empresa minera | F21: 2QRX+9M Lucainena de las Torres | G21: C. Juan Pablo II, 10, 04210 Lucainena de las Torres, Almería | H21: Lucainena de las Torres | I21: Almería | L21: - | M21: Sí | N21: 37.0409017 | O21: -2.2008412 | P21: https://goo.gl/maps/VQuMcE9yKGYC7pC1A | Q21: <iframe src="https://www.google.com/maps/embed?pb=!1m18!1m12!1m3!1d25477.565460491365!2d-2.2183506604492185!3d37.0409017!2m3!1f0!2f0!3f0!3m2!1i1024!2i768!4f13.1!3m3!1m2!1s0xd7ac75000000001%3A0x86029fcc8cb93820!2sSegura!5e0!3m2!1ses!2ses!4v1651828946121!5m2!1ses!2ses" width="600" height="450" style="border:0;" allowfullscreen="" loading="lazy" referrerpolicy="no-referrer-when-downgrade"></iframe> | R21: https://streetviewpixels-pa.googleapis.com/v1/thumbnail?panoid=GGHDgkYQiiQtujUES6IXNg&cb_client=search.gws-prod.gps&w=408&h=240&yaw=316.67154&pitch=0&thumbfov=100
A22: Luis Estévez E Hijos | F22: RGQQ+G3 Almería | G22: C. Minero, 2, 04001 Almería | H22: Almería | I22: Almería | L22: - | M22: Sí | N22: 36.83885 | O22: -2.46226 | P22: https://goo.gl/maps/VQzKLUUoffxLCAkm8 | Q22: <iframe src="https://www.google.com/maps/embed?pb=!1m18!1m12!1m3!1d25545.21118370273!2d-2.4797694604492184!3d36.83885000000001!2m3!1f0!2f0!3f0!3m2!1i1024!2i768!4f13.1!3m3!1m2!1s0xd707601a4a76137%3A0xb5759707184235e7!2sLuis%20Est%C3%A9vez%20E%20Hijos!5e0!3m2!1ses!2ses!4v1651828952341!5m2!1ses!2ses" width="600" height="450" style="border:0;" allowfullscreen="" loading="lazy" referrerpolicy="no-referrer-when-downgrade"></iframe> | R22: https://streetviewpixels-pa.googleapis.com/v1/thumbnail?panoid=TyOlrXO0yF-D0IIrL_uIqg&cb_client=search.gws-prod.gps&w=408&h=240&yaw=164.96098&pitch=0&thumbfov=100
A23: El Cable Inglés | B23: Lugar de interés histórico | C23: 4,4 | D23: 242 | E23: viernes, Abierto 24 horas; sábado, Abierto 24 horas; domingo, Abierto 24 horas; lunes, Abierto 24 horas; martes, Abierto 24 horas; miércoles, Abierto 24 horas; jueves, Abierto 24 horas | F23: RGJP+QJ Almería | G23: 04007 Almería | H23: Almería | I23: Almería | L23: - | M23: Sí | N23: 36.8319927 | O23: -2.4634833 | P23: https://goo.gl/maps/drtu8pXDptUSKxPB8 | Q23: <iframe src="https://www.google.com/maps/embed?pb=!1m18!1m12!1m3!1d25545.23399647806!2d-2.479838660449219!3d36.8387817!2m3!1f0!2f0!3f0!3m2!1i1024!2i768!4f13.1!3m3!1m2!1s0xd707712b1e5caad%3A0x41dc8f4dd4e4e00c!2sEl%20Cable%20Ingl%C3%A9s!5e0!3m2!1ses!2ses!4v1651828979934!5m2!1ses!2ses" width="600" height="450" style="border:0;" allowfullscreen="" loading="lazy" referrerpolicy="no-referrer-when-downgrade"></iframe> | R23: https://lh5.googleusercontent.com/p/AF1QipOJZJeKvJ2E9_u3X_k4cfg4clPqCygnba_oKKx4=w408-h305-k-no
A24: Minas de Gádor | B24: Lugar de interés histórico | C24: 5,0 | D24: 1 | F24: WFH7+98 Gádor | G24: 04560 Gádor, Almería | H24: Gádor | I24: Almería | L24: - | M24: Sí | N24: 36.9284412 | O24: -2.5366715 | P24: https://goo.gl/maps/QWwhFkfKGPkyyWK56 | Q24: <iframe src="https://www.google.com/maps/embed?pb=!1m18!1m12!1m3!1d25515.25572712748!2d-2.5541809604492185!3d36.92844120000001!2m3!1f0!2f0!3f0!3m2!1i1024!2i768!4f13.1!3m3!1m2!1s0xd700b862d3e8fc3%3A0x3bc3b34eaaa1de6e!2sMinas%20de%20G%C3%A1dor!5e0!3m2!1ses!2ses!4v1651828986934!5m2!1ses!2ses" width="600" height="450" style="border:0;" allowfullscreen="" loading="lazy" referrerpolicy="no-referrer-when-downgrade"></iframe> | R24: https://lh5.googleusercontent.com/p/AF1QipMQZcF7i06x0m5ctSLtvl6xselgf4oCiE0ZAroa=w408-h544-k-no
A25: Minas de la Solana | B25: Ruta por explotaciones agrícolas | C25: 5,0 | D25: 1 | F25: X5RH+2G Fondón | G25: Unnamed Road, 04458, Almería | H25: Fondón | I25: Almería | L25: - | M25: Sí | N25: 36.9900245 | O25: -2.8211354 | P25: https://goo.gl/maps/gMrgcS76XGHS12uv5 | Q25: <iframe src="https://www.google.com/maps/embed?pb=!1m18!1m12!1m3!1d25494.628727410258!2d-2.8386448604492185!3d36.9900245!2m3!1f0!2f0!3f0!3m2!1i1024!2i768!4f13.1!3m3!1m2!1s0xd703fb616f1b573%3A0x9de393ed1ea10fe!2sMinas%20de%20la%20Solana!5e0!3m2!1ses!2ses!4v1651829006496!5m2!1ses!2ses" width="600" height="450" style="border:0;" allowfullscreen="" loading="lazy" referrerpolicy="no-referrer-when-downgrade"></iframe> | R25: https://lh5.googleusercontent.com/p/AF1QipNrfU9I12rWYXZd4Ug2G6j7nA2T8uff4i-8KSVY=w408-h240-k-no-pi-20-ya240-ro0-fo100
A26: Centro de Interpretación de la Minería de Beires | B26: Museo | F26: 2665+GF Beires | G26: 04458 Beires, Almería | H26: Beires | I26: Almería | L26: - | M26: Sí | N26: 37.0112477 | O26: -2.7912278 | P26: https://goo.gl/maps/tEEDZDkCWNkS6Ka17 | Q26: <iframe src="https://www.google.com/maps/embed?pb=!1m18!1m12!1m3!1d25487.50585902929!2d-2.808795560449218!3d37.0112699!2m3!1f0!2f0!3f0!3m2!1i1024!2i768!4f13.1!3m3!1m2!1s0xd703dcee7f10d47%3A0x766082e6355c81d3!2sCentro%20de%20Interpretaci%C3%B3n%20de%20la%20Miner%C3%ADa%20de%20Beires!5e0!3m2!1ses!2ses!4v1651829060497!5m2!1ses!2ses" width="600" height="450" style="border:0;" allowfullscreen="" loading="lazy" referrerpolicy="no-referrer-when-downgrade"></iframe> | R26: https://streetviewpixels-pa.googleapis.com/v1/thumbnail?panoid=JCFiK43kKFK0eN8XS4ayhg&cb_client=search.gws-prod.gps&w=408&h=240&yaw=284.80847&pitch=0&thumbfov=100
A27: Amigos de la Alcazaba de Almería | B27: Oficinas de empresa | C27: 4,7 | D27: 3 | E27: viernes, De 9:00 a 15:30, De 18:30 a 22:00; sábado, De 9:00 a 15:30, De 18:30 a 22:00; domingo, De 10:00 a 17:00; lunes, Cerrado; martes, De 9:00 a 15:30, De 18:30 a 22:00; miércoles, De 9:00 a 15:30, De 18:30 a 22:00; jueves, De 9:00 a 15:30, De 18:30 a 22:00 | F27: RGQJ+H5 Almería | G27: C. de la Almedina, 16, 04002 Almería | H27: Almería | I27: Almería | J27: amigosdelaalcazaba.org | K27: 608 04 70 08 | L27: asociacion@amigosdelaalcazaba.org | M27: Sí | N27: 36.8389475 | O27: -2.469605 | P27: https://goo.gl/maps/bFvQ6naosScugN5cA | Q27: <iframe src="https://www.google.com/maps/embed?pb=!1m18!1m12!1m3!1d25545.17801660152!2d-2.487115260449219!3d36.83894930000001!2m3!1f0!2f0!3f0!3m2!1i1024!2i768!4f13.1!3m3!1m2!1s0xd7076063b17c725%3A0x2a33ac7ab506b401!2sAmigos%20de%20la%20Alcazaba%20de%20Almer%C3%ADa!5e0!3m2!1ses!2ses!4v1651829067481!5m2!1ses!2ses" width="600" height="450" style="border:0;" allowfullscreen="" loading="lazy" referrerpolicy="no-referrer-when-downgrade"></iframe> | R27: https://lh5.googleusercontent.com/p/AF1QipO7PcCYVOqXoGDuBMymVHFA-ss_mwKPSJeJAAJx=w408-h544-k-no
A28: Mina María Josefa | B28: Mina | C28: 4,0 | D28: 1 | F28: VW58+V9 Albaricoques | G28: 04116, Almería | H28: Albaricoques | I28: Almería | L28: - | M28: Sí | N28: 36.859666 | O28: -2.0840552 | P28: https://goo.gl/maps/CnQjV3gUU2c21rSK8 | Q28: <iframe src="https://www.google.com/maps/embed?pb=!1m18!1m12!1m3!1d25538.256773091554!2d-2.1015646604492186!3d36.859666!2m3!1f0!2f0!3f0!3m2!1i1024!2i768!4f13.1!3m3!1m2!1s0xd7aebf28ea2fc51%3A0xe326d27f2e0ec1a7!2sMina%20Mar%C3%ADa%20Josefa!5e0!3m2!1ses!2ses!4v1651829092387!5m2!1ses!2ses" width="600" height="450" style="border:0;" allowfullscreen="" loading="lazy" referrerpolicy="no-referrer-when-downgrade"></iframe> | R28: https://lh5.googleusercontent.com/p/AF1QipMueoBsbd9SIwZ5uuWv-IWrFNehQPXly5JAyVN-=w426-h240-k-no
A29: Técnicos Consultores Del Sureste S L | B29: Topógrafo | C29: 3,0 | D29: 2 | F29: RHV3+JH Almería | G29: C. Fray Bernardo Martínez Noval, 7, 04006 Almería | H29: Almería | I29: Almería | K29: 950 22 00 82 | L29: - | M29: Sí | N29: 36.8440828 | O29: -2.446094 | P29: https://goo.gl/maps/47ubfF9peHU3Zu9t8 | Q29: <iframe src="https://www.google.com/maps/embed?pb=!1m18!1m12!1m3!1d25543.46334330833!2d-2.463593160449196!3d36.84408259999999!2m3!1f0!2f0!3f0!3m2!1i1024!2i768!4f13.1!3m3!1m2!1s0xd7a9e09f230aa1b%3A0x4fe8767933714e3c!2sT%C3%A9cnicos%20Consultores%20Del%20Sureste%20S%20L!5e0!3m2!1ses!2ses!4v1651829104340!5m2!1ses!2ses" width="600" height="450" style="border:0;" allowfullscreen="" loading="lazy" referrerpolicy="no-referrer-when-downgrade"></iframe> | R29: https://streetviewpixels-pa.googleapis.com/v1/thumbnail?panoid=Q6rUSQZEFvvXPY0L9-OoFg&cb_client=search.gws-prod.gps&w=408&h=240&yaw=222.41898&pitch=0&thumbfov=100
A30: Monumento al Minero | B30: Lugar de interés histórico | C30: 5,0 | D30: 2 | E30: viernes, Abierto 24 horas; sábado, Abierto 24 horas; domingo, Abierto 24 horas; lunes, Abierto 24 horas; martes, Abierto 24 horas; miércoles, Abierto 24 horas; jueves, Abierto 24 horas | F30: 52R9+7P Bédar | G30: C. San Gregorio, 04288 Bédar, Almería | H30: Bédar | I30: Almería | L30: - | M30: Sí | N30: 37.190681 | O30: -1.9807396 | P30: https://goo.gl/maps/JYQARdUW567LWxCn9 | Q30: <iframe src="https://www.google.com/maps/embed?pb=!1m18!1m12!1m3!1d25427.217513275657!2d-1.9982076604492187!3d37.19067560000001!2m3!1f0!2f0!3f0!3m2!1i1024!2i768!4f13.1!3m3!1m2!1s0xd7ad12482cb7721%3A0x14e8910e83a8db61!2sMonumento%20al%20Minero!5e0!3m2!1ses!2ses!4v1651829123888!5m2!1ses!2ses" width="600" height="450" style="border:0;" allowfullscreen="" loading="lazy" referrerpolicy="no-referrer-when-downgrade"></iframe> | R30: https://lh5.googleusercontent.com/p/AF1QipNmjyBwejonhRtKpDaqmTvme-X-9Jp_vdSJ5wzg=w408-h306-k-no
A31: Centro De Interpretación Casa Don Mariano | B31: Museo de artesanía | C31: 4,0 | D31: 1 | F31: XG27+6V Gádor | G31: 04560 Gádor, Almería | H31: Gádor | I31: Almería | J31: gador.es | K31: 950 64 52 11 | L31: - | M31: Sí | N31: 36.9505022 | O31: -2.4851972 | P31: https://goo.gl/maps/fADKuojc1hjnWMB5A | Q31: <iframe src="https://www.google.com/maps/embed?pb=!1m18!1m12!1m3!1d25507.861025081776!2d-2.5027631604492195!3d36.9505287!2m3!1f0!2f0!3f0!3m2!1i1024!2i768!4f13.1!3m3!1m2!1s0xd700bea203faded%3A0xe8b657dd0e6f3e32!2sCentro%20De%20Interpretaci%C3%B3n%20Casa%20Don%20Mariano!5e0!3m2!1ses!2ses!4v1651829136184!5m2!1ses!2ses" width="600" height="450" style="border:0;" allowfullscreen="" loading="lazy" referrerpolicy="no-referrer-when-downgrade"></iframe> | R31: https://lh5.googleusercontent.com/p/AF1QipOY6VvHFpqAM_iryGoz8MCxz2IKvsyQg-7evw-f=w408-h272-k-no
A32: Edison | F32: RGQQ+H4 Almería | G32: C. Minero, 2, 04001 Almería | H32: Almería | I32: Almería | L32: - | M32: Sí | N32: 36.8389162 | O32: -2.4621581 | P32: https://goo.gl/maps/kmbEnfQetAjnxw9c6 | Q32: <iframe src="https://www.google.com/maps/embed?pb=!1m18!1m12!1m3!1d25545.189072310448!2d-2.4796675604492187!3d36.83891620000001!2m3!1f0!2f0!3f0!3m2!1i1024!2i768!4f13.1!3m3!1m2!1s0xd707601bc923fcd%3A0xac96b777375a3b2d!2sEdison!5e0!3m2!1ses!2ses!4v1651829142277!5m2!1ses!2ses" width="600" height="450" style="border:0;" allowfullscreen="" loading="lazy" referrerpolicy="no-referrer-when-downgrade"></iframe> | R32: https://streetviewpixels-pa.googleapis.com/v1/thumbnail?panoid=gx74uHnOVx19NwrE36ESRg&cb_client=search.gws-prod.gps&w=408&h=240&yaw=262.364&pitch=0&thumbfov=100
A33: Viviendas Rurales | B33: Empresa constructora | F33: RGQQ+H5 Almería | G33: C. Minero, 4, 04001 Almería | H33: Almería | I33: Almería | K33: 950 27 44 52 | L33: - | M33: Sí | N33: 36.8389525 | O33: -2.4620378 | P33: https://goo.gl/maps/drb2cxt8BhbKV89M9 | Q33: <iframe src="https://www.google.com/maps/embed?pb=!1m18!1m12!1m3!1d25545.189072310448!2d-2.4796675604492187!3d36.83891620000001!2m3!1f0!2f0!3f0!3m2!1i1024!2i768!4f13.1!3m3!1m2!1s0xd707601bc72d261%3A0xf91dfd492a0ee693!2sViviendas%20Rurales!5e0!3m2!1ses!2ses!4v1651829148340!5m2!1ses!2ses" width="600" height="450" style="border:0;" allowfullscreen="" loading="lazy" referrerpolicy="no-referrer-when-downgrade"></iframe> | R33: https://streetviewpixels-pa.googleapis.com/v1/thumbnail?panoid=s0IsgXhOCek5YnWN-2FUyQ&cb_client=search.gws-prod.gps&w=408&h=240&yaw=229.61386&pitch=0&thumbfov=100
A34: Explotaciones Río De Aguas S L | B34: Contratista de excavación | C34: 5,0 | D34: 2 | F34: 3V7R+X8 Sorbas | G34: Lugar Barriada El Hueli, s/n, 04270 Hueli, Almería | H34: Sorbas | I34: Almería | K34: 950 36 44 00 | L34: - | M34: Sí | N34: 37.06499 | O34: -2.10913 | P34: https://goo.gl/maps/EKVQXooimmwdyp3w5 | Q34: <iframe src="https://www.google.com/maps/embed?pb=!1m18!1m12!1m3!1d25469.47968442922!2d-2.126639460449219!3d37.064989999999995!2m3!1f0!2f0!3f0!3m2!1i1024!2i768!4f13.1!3m3!1m2!1s0xd7ac7aa6dfd670d%3A0x7706546460073507!2sExplotaciones%20R%C3%ADo%20De%20Aguas%20S%20L!5e0!3m2!1ses!2ses!4v1651829154465!5m2!1ses!2ses" width="600" height="450" style="border:0;" allowfullscreen="" loading="lazy" referrerpolicy="no-referrer-when-downgrade"></iframe> | R34: https://lh5.googleusercontent.com/p/AF1QipMEHHWxJu2I2oZ23MTS86JOKEQNWgh7QEOUVfCv=w408-h306-k-no
A35: Mármoles Rosmar | B35: Empresa de mármoles | C35: 4,7 | D35: 12 | E35: viernes, De 8:15 a 13:00, De 15:00 a 19:00; sábado, Cerrado; domingo, Cerrado; lunes, De 8:15 a 13:00, De 15:00 a 19:00; martes, De 8:15 a 13:00, De 15:00 a 19:00; miércoles, De 8:15 a 13:00, De 15:00 a 19:00; jueves, De 8:15 a 13:00, De 15:00 a 19:00 | F35: RHR7+P6 Almería | G35: C. Mármoles, 29, 04007 Almería | H35: Almería | I35: Almería | K35: 950 22 44 37 | L35: - | M35: Sí | N35: 36.8417863 | O35: -2.4369025 | P35: https://goo.gl/maps/QPWsJsurHiBLi7Eo6 | Q35: <iframe src="https://www.google.com/maps/embed?pb=!1m18!1m12!1m3!1d25544.219845042822!2d-2.454387760449219!3d36.84181789999999!2m3!1f0!2f0!3f0!3m2!1i1024!2i768!4f13.1!3m3!1m2!1s0xd7a9ddf14d538fb%3A0x2c1c57b22af0bfca!2sM%C3%A1rmoles%20Rosmar!5e0!3m2!1ses!2ses!4v1651829169919!5m2!1ses!2ses" width="600" height="450" style="border:0;" allowfullscreen="" loading="lazy" referrerpolicy="no-referrer-when-downgrade"></iframe> | R35: https://lh5.googleusercontent.com/p/AF1QipOvgHj16I7CweNEwvAdtSsVanJQ7iQUjk4omqaX=w426-h240-k-no
A36: Instituto Español de Investigación de Estudios Avanzados - IEIEA | B36: Escuela de estudios superiores de posgrado | E36: viernes, De 8:00 a 20:00; sábado, De 10:00 a 14:00; domingo, Cerrado; lunes, De 8:00 a 20:00; martes, De 8:00 a 20:00; miércoles, De 8:00 a 20:00; jueves, De 8:00 a 20:00 | F36: RGQQ+H7 Almería | G36: C. Minero, 8, 04001 Almería | H36: Almería | I36: Almería | K36: 950 25 85 44 | L36: - | M36: No | N36: 36.8389515 | O36: -2.4617941 | P36: https://goo.gl/maps/DTXaoLhn7R22hgX28 | Q36: <iframe src="https://www.google.com/maps/embed?pb=!1m18!1m12!1m3!1d25545.176947771197!2d-2.4795472604492503!3d36.83895250000002!2m3!1f0!2f0!3f0!3m2!1i1024!2i768!4f13.1!3m3!1m2!1s0xd707601bf2885b1%3A0x931d0b3ce91255fe!2sInstituto%20Espa%C3%B1ol%20de%20Investigaci%C3%B3n%20de%20Estudios%20Avanzados%20-%20IEIEA!5e0!3m2!1ses!2ses!4v1651829216091!5m2!1ses!2ses" width="600" height="450" style="border:0;" allowfullscreen="" loading="lazy" referrerpolicy="no-referrer-when-downgrade"></iframe> | R36: https://lh5.googleusercontent.com/p/AF1QipPIeK2-CypPCtNyO-jUr9btSlPpfgjm41_niOsm=w408-h306-k-no
A37: Galería de Los Lobos | B37: Mina | C37: 3,0 | D37: 1 | F37: R54H+W9 El Ejido | G37: Unnamed Road, 04715, Almería | H37: El Ejido | I37: Almería | L37: - | M37: Sí | N37: 36.8072567 | O37: -2.8215612 | P37: https://goo.gl/maps/sUPMbRH6wwZctgqR6 | Q37: <iframe src="https://www.google.com/maps/embed?pb=!1m18!1m12!1m3!1d25555.75973638268!2d-2.8390706604492184!3d36.807256699999996!2m3!1f0!2f0!3f0!3m2!1i1024!2i768!4f13.1!3m3!1m2!1s0xd704334f6206c85%3A0x6a1451c3c82c3746!2sGaler%C3%ADa%20de%20Los%20Lobos!5e0!3m2!1ses!2ses!4v1651829249309!5m2!1ses!2ses" width="600" height="450" style="border:0;" allowfullscreen="" loading="lazy" referrerpolicy="no-referrer-when-downgrade"></iframe>
A38: Minas de Alquife | B38: Mina | C38: 4,1 | D38: 13 | F38: 5VHP+Q5 Alquife | G38: Barriada de Minas del Marquesado, s/n, 18518 Alquife, Granada | H38: Alquife | I38: Granada | J38: alquifemines.com | L38: - | M38: No | N38: 37.1794947 | O38: -3.1146216 | P38: https://goo.gl/maps/2DAXffQd9YoYjPwA8 | Q38: <iframe src="https://www.google.com/maps/embed?pb=!1m18!1m12!1m3!1d25430.9820866196!2d-3.1321310604492187!3d37.1794947!2m3!1f0!2f0!3f0!3m2!1i1024!2i768!4f13.1!3m3!1m2!1s0xd71d4bebc1688d1%3A0xcd7b1a98df7b88a7!2sMinas%20de%20Alquife!5e0!3m2!1ses!2ses!4v1651829263153!5m2!1ses!2ses" width="600" height="450" style="border:0;" allowfullscreen="" loading="lazy" referrerpolicy="no-referrer-when-downgrade"></iframe> | R38: https://lh5.googleusercontent.com/p/AF1QipOzgOZaAQ34nZUg6JEZ_qiR9PCT4WI4ZCr4vMPA=w408-h262-k-no
A39: Torre de los Alumbres | B39: Lugar de interés histórico | C39: 4,0 | D39: 55 | E39: viernes, Abierto 24 horas; sábado, Abierto 24 horas; domingo, Abierto 24 horas; lunes, Abierto 24 horas; martes, Abierto 24 horas; miércoles, Abierto 24 horas; jueves, Abierto 24 horas | F39: VX4P+52 Níjar | G39: 04115 Níjar, Almería | H39: Níjar | I39: Almería | K39: 950 52 51 37 | L39: - | M39: Sí | N39: 36.8555144 | O39: -2.0149463 | P39: https://goo.gl/maps/Fc5EBF3HVSZWrHJC8 | Q39: <iframe src="https://www.google.com/maps/embed?pb=!1m18!1m12!1m3!1d25539.662560160148!2d-2.032470160449219!3d36.855459!2m3!1f0!2f0!3f0!3m2!1i1024!2i768!4f13.1!3m3!1m2!1s0xd7ae8cc337cb295%3A0xf47ef4554748788e!2sTorre%20de%20los%20Alumbres!5e0!3m2!1ses!2ses!4v1651829269325!5m2!1ses!2ses" width="600" height="450" style="border:0;" allowfullscreen="" loading="lazy" referrerpolicy="no-referrer-when-downgrade"></iframe> | R39: https://lh5.googleusercontent.com/p/AF1QipO8gMsOacH7TtusvuoP4cJIbd8Ac6ZZESfjU4BP=w408-h544-k-no
A40: Mina romana de lapis specularis del Espejuelo | C40: 4,4 | D40: 14 | F40: CW3P+W3 Arboleas | G40: 04661 Arboleas, Almería | H40: Arboleas | I40: Almería | J40: arboleas.org | K40: 950 44 94 30 | L40: - | M40: Sí | N40: 37.4048035 | O40: -2.0648623 | P40: https://goo.gl/maps/wCYnLD5S6pjor6EbA | Q40: <iframe src="https://www.google.com/maps/embed?pb=!1m18!1m12!1m3!1d25354.934658167367!2d-2.0823717604492185!3d37.404803499999986!2m3!1f0!2f0!3f0!3m2!1i1024!2i768!4f13.1!3m3!1m2!1s0xd65312b1d86f985%3A0x55a0ba35f2d56ad4!2sMina%20romana%20de%20lapis%20specularis%20del%20Espejuelo!5e0!3m2!1ses!2ses!4v1651829275652!5m2!1ses!2ses" width="600" height="450" style="border:0;" allowfullscreen="" loading="lazy" referrerpolicy="no-referrer-when-downgrade"></iframe> | R40: https://lh5.googleusercontent.com/p/AF1QipNQUDAeGbGPHUkv-p41yaBjFKrKnc-OKGPlZHre=w408-h272-k-no
...

Sheet Minas
A1: ﻿Nombre | B1: Categoría | C1: Rating | D1: Nº Reviews | E1: Horario | F1: Código Plus | G1: Direccion | H1: Localidad | I1: Provincia | J1: Website | K1: Teléfono | L1: email | M1: Reclamar | N1: Latitud | O1: Longitud | P1: Url en Maps | Q1: Iframe | R1: Imagen Url
A2: Mina de Talco | B2: Mina | C2: 4,7 | D2: 3 | E2: viernes, Abierto 24 horas; sábado, Abierto 24 horas; domingo, Abierto 24 horas; lunes, Abierto 24 horas; martes, Abierto 24 horas; miércoles, Abierto 24 horas; jueves, Abierto 24 horas | F2: VG3C+9W Almería | G2: Acceso a A-7, 04008 Almería | H2: Almería | I2: Almería | L2: - | M2: Sí | N2: 36.8534497 | O2: -2.4776319 | P2: https://goo.gl/maps/H7zr6KFoZGtTPcYe8 | Q2: <iframe src="https://www.google.com/maps/embed?pb=!1m18!1m12!1m3!1d102177.29575124479!2d-2.5096470540265146!3d36.84150627352816!2m3!1f0!2f0!3f0!3m2!1i1024!2i768!4f13.1!3m3!1m2!1s0xd7075e3c8d5c031%3A0xb3a18684c09ff2ed!2sMina%20de%20Talco!5e0!3m2!1ses!2ses!4v1651828762041!5m2!1ses!2ses" width="600" height="450" style="border:0;" allowfullscreen="" loading="lazy" referrerpolicy="no-referrer-when-downgrade"></iframe> | R2: https://lh5.googleusercontent.com/p/AF1QipNYA_-JNgsH10SzKiBpJER4nVp8QOnuUIR-QQmX=w408-h544-k-no
A3: Minas De Rodalquilar | B3: Mina | C3: 4,3 | D3: 108 | E3: viernes, Abierto 24 horas; sábado, Abierto 24 horas; domingo, Abierto 24 horas; lunes, Abierto 24 horas; martes, Abierto 24 horas; miércoles, Abierto 24 horas; jueves, Abierto 24 horas | F3: VX33+87 Níjar | G3: C. Apartadero, 9, 04115 Níjar, Almería | H3: Níjar | I3: Almería | L3: - | M3: Sí | N3: 36.8532568 | O3: -2.0467748 | P3: https://goo.gl/maps/SD9PnMMPdjKsf6qAA | Q3: <iframe src="https://www.google.com/maps/embed?pb=!1m18!1m12!1m3!1d102161.5935192764!2d-2.1168126417968627!3d36.853256800000004!2m3!1f0!2f0!3f0!3m2!1i1024!2i768!4f13.1!3m3!1m2!1s0xd7ae953d0696c25%3A0x8a62f495a746f766!2sMinas%20De%20Rodalquilar!5e0!3m2!1ses!2ses!4v1651828776746!5m2!1ses!2ses" width="600" height="450" style="border:0;" allowfullscreen="" loading="lazy" referrerpolicy="no-referrer-when-downgrade"></iframe> | R3: https://lh5.googleusercontent.com/p/AF1QipM7JNxYV8MiPi3HM41YePyLgqPUWbAgqo8XW1CK=w426-h240-k-no
A4: Minas del Carmen | B4: Mina | C4: 4,0 | D4: 4 | F4: V9P9+WX El Marchal de Antón López | G4: Barranco de Plateros, 04729 El Marchal de Antón López, Almería | H4: El Marchal de Antón López | I4: Almería | L4: - | M4: Sí | N4: 36.8872855 | O4: -2.6301245 | P4: https://goo.gl/maps/zfidVebut4PraLzH7 | Q4: <iframe src="https://www.google.com/maps/embed?pb=!1m18!1m12!1m3!1d102116.09672020565!2d-2.700162341796924!3d36.88728550000001!2m3!1f0!2f0!3f0!3m2!1i1024!2i768!4f13.1!3m3!1m2!1s0xd706d77358504af%3A0x37b9100bdcc479e!2sMinas%20del%20Carmen!5e0!3m2!1ses!2ses!4v1651828788372!5m2!1ses!2ses" width="600" height="450" style="border:0;" allowfullscreen="" loading="lazy" referrerpolicy="no-referrer-when-downgrade"></iframe> | R4: https://lh5.googleusercontent.com/p/AF1QipPwoDRQBuprdGz2YFbXC241WUL55fdjpLrXuSV9=w408-h663-k-no
A5: Coto Láisquez | B5: Mina | C5: 5,0 | D5: 1 | F5: XPPW+R2 Huebro | G5: 04119, Almería | H5: Huebro | I5: Almería | L5: - | M5: Sí | N5: 36.9870472 | O5: -2.2549732 | P5: https://goo.gl/maps/WWaxpbBjMZybCnaB7 | Q5: <iframe src="https://www.google.com/maps/embed?pb=!1m18!1m12!1m3!1d101982.50654396469!2d-2.325011041796891!3d36.98704719999999!2m3!1f0!2f0!3f0!3m2!1i1024!2i768!4f13.1!3m3!1m2!1s0xd7abc5a9ac3a90d%3A0xf7da6cb6cc27f67!2sCoto%20L%C3%A1isquez!5e0!3m2!1ses!2ses!4v1651828795700!5m2!1ses!2ses" width="600" height="450" style="border:0;" allowfullscreen="" loading="lazy" referrerpolicy="no-referrer-when-downgrade"></iframe> | R5: https://lh5.googleusercontent.com/p/AF1QipMYoUFQJt3hJsAjeZV-P92PkECTwivwkSYagNmG=w408-h306-k-no
A6: Ingeniera Técnica Minera Fadrique | B6: Ingeniero de minas | E6: viernes, De 7:00 a 20:00; sábado, De 7:00 a 14:00; domingo, Cerrado; lunes, De 7:00 a 20:00; martes, De 7:00 a 20:00; miércoles, De 7:00 a 20:00; jueves, De 7:00 a 20:00 | F6: R9MQ+9C La Envía | G6: Calle de los Nogales, 25, 04727 La Envía, Almería | H6: La Envía | I6: Almería | K6: 655 64 34 85 | L6: - | M6: No | N6: 36.8333937 | O6: -2.6114838 | P6: https://goo.gl/maps/KxMmiMVJdCop3rMB9 | Q6: <iframe src="https://www.google.com/maps/embed?pb=!1m18!1m12!1m3!1d102188.12606272443!2d-2.681470341796881!3d36.833399700000015!2m3!1f0!2f0!3f0!3m2!1i1024!2i768!4f13.1!3m3!1m2!1s0xd707114dd75b5f1%3A0x56f1858ef64cd51e!2sIngeniera%20T%C3%A9cnica%20Minera%20Fadrique!5e0!3m2!1ses!2ses!4v1651828801903!5m2!1ses!2ses" width="600" height="450" style="border:0;" allowfullscreen="" loading="lazy" referrerpolicy="no-referrer-when-downgrade"></iframe>
A7: Poblado minero de San Diego | B7: Mina | C7: 4,7 | D7: 9 | E7: viernes, Abierto 24 horas; sábado, Abierto 24 horas; domingo, Abierto 24 horas; lunes, Abierto 24 horas; martes, Abierto 24 horas; miércoles, Abierto 24 horas; jueves, Abierto 24 horas | F7: RWXM+7W Níjar | G7: 04115 Níjar, Almería | H7: Níjar | I7: Almería | L7: - | M7: Sí | N7: 36.84815 | O7: -2.0651921 | P7: https://goo.gl/maps/D7BfbL3PA9u6PSAk9 | Q7: <iframe src="https://www.google.com/maps/embed?pb=!1m18!1m12!1m3!1d102168.41826557778!2d-2.1352299417968745!3d36.84815000000001!2m3!1f0!2f0!3f0!3m2!1i1024!2i768!4f13.1!3m3!1m2!1s0xd7aeeaaf2909097%3A0x386f3f166850bbf8!2sPoblado%20minero%20de%20San%20Diego!5e0!3m2!1ses!2ses!4v1651828809200!5m2!1ses!2ses" width="600" height="450" style="border:0;" allowfullscreen="" loading="lazy" referrerpolicy="no-referrer-when-downgrade"></iframe> | R7: https://lh5.googleusercontent.com/p/AF1QipO09354IuIgbGZU2eDfYwYEx4EyVn2WhgWSMCh3=w408-h306-k-no
A8: Mina María Josefa | B8: Mina | C8: 4,0 | D8: 1 | F8: VW58+V9 Albaricoques | G8: 04116, Almería | H8: Albaricoques | I8: Almería | L8: - | M8: Sí | N8: 36.859666 | O8: -2.0840552 | P8: https://goo.gl/maps/CnQjV3gUU2c21rSK8 | Q8: <iframe src="https://www.google.com/maps/embed?pb=!1m18!1m12!1m3!1d25538.256773091554!2d-2.1015646604492186!3d36.859666!2m3!1f0!2f0!3f0!3m2!1i1024!2i768!4f13.1!3m3!1m2!1s0xd7aebf28ea2fc51%3A0xe326d27f2e0ec1a7!2sMina%20Mar%C3%ADa%20Josefa!5e0!3m2!1ses!2ses!4v1651829092387!5m2!1ses!2ses" width="600" height="450" style="border:0;" allowfullscreen="" loading="lazy" referrerpolicy="no-referrer-when-downgrade"></iframe> | R8: https://lh5.googleusercontent.com/p/AF1QipMueoBsbd9SIwZ5uuWv-IWrFNehQPXly5JAyVN-=w426-h240-k-no
A9: Galería de Los Lobos | B9: Mina | C9: 3,0 | D9: 1 | F9: R54H+W9 El Ejido | G9: Unnamed Road, 04715, Almería | H9: El Ejido | I9: Almería | L9: - | M9: Sí | N9: 36.8072567 | O9: -2.8215612 | P9: https://goo.gl/maps/sUPMbRH6wwZctgqR6 | Q9: <iframe src="https://www.google.com/maps/embed?pb=!1m18!1m12!1m3!1d25555.75973638268!2d-2.8390706604492184!3d36.807256699999996!2m3!1f0!2f0!3f0!3m2!1i1024!2i768!4f13.1!3m3!1m2!1s0xd704334f6206c85%3A0x6a1451c3c82c3746!2sGaler%C3%ADa%20de%20Los%20Lobos!5e0!3m2!1ses!2ses!4v1651829249309!5m2!1ses!2ses" width="600" height="450" style="border:0;" allowfullscreen="" loading="lazy" referrerpolicy="no-referrer-when-downgrade"></iframe>
A10: Minas de Alquife | B10: Mina | C10: 4,1 | D10: 13 | F10: 5VHP+Q5 Alquife | G10: Barriada de Minas del Marquesado, s/n, 18518 Alquife, Granada | H10: Alquife | I10: Granada | J10: alquifemines.com | L10: - | M10: No | N10: 37.1794947 | O10: -3.1146216 | P10: https://goo.gl/maps/2DAXffQd9YoYjPwA8 | Q10: <iframe src="https://www.google.com/maps/embed?pb=!1m18!1m12!1m3!1d25430.9820866196!2d-3.1321310604492187!3d37.1794947!2m3!1f0!2f0!3f0!3m2!1i1024!2i768!4f13.1!3m3!1m2!1s0xd71d4bebc1688d1%3A0xcd7b1a98df7b88a7!2sMinas%20de%20Alquife!5e0!3m2!1ses!2ses!4v1651829263153!5m2!1ses!2ses" width="600" height="450" style="border:0;" allowfullscreen="" loading="lazy" referrerpolicy="no-referrer-when-downgrade"></iframe> | R10: https://lh5.googleusercontent.com/p/AF1QipOzgOZaAQ34nZUg6JEZ_qiR9PCT4WI4ZCr4vMPA=w408-h262-k-no
A11: Minas Tres Pacos | B11: Ingeniero de minas | C11: 4,3 | D11: 16 | F11: 84MG+CQ Cuevas del Almanzora | G11: Unnamed Road,, 04619 Cuevas del Almanzora, Almería | H11: Cuevas del Almanzora | I11: Almería | L11: - | M11: Sí | N11: 37.3335611 | O11: -1.8730926 | P11: https://goo.gl/maps/iwjS9r6RAreQThxQ6 | Q11: <iframe src="https://www.google.com/maps/embed?pb=!1m18!1m12!1m3!1d25379.02321611813!2d-1.890602060449219!3d37.3335611!2m3!1f0!2f0!3f0!3m2!1i1024!2i768!4f13.1!3m3!1m2!1s0xd652baddf7397a3%3A0xf04d92260aa7f910!2sMinas%20Tres%20Pacos!5e0!3m2!1ses!2ses!4v1651829301372!5m2!1ses!2ses" width="600" height="450" style="border:0;" allowfullscreen="" loading="lazy" referrerpolicy="no-referrer-when-downgrade"></iframe> | R11: https://lh5.googleusercontent.com/p/AF1QipMJEKPLXZsfoj6n7N6dTSYZrW1WMAlQTX4svH4Z=w426-h240-k-no
A12: Minas de hierro del Cerro del Conjuro | B12: Mina | C12: 3,0 | D12: 1 | F12: WPG7+R6 Cástaras | G12: 18439 Cástaras, Granada | H12: Cástaras | I12: Granada | J12: turgranada.es | L12: fjtitos@turgranada.es | M12: Sí | N12: 36.9271055 | O12: -3.2868322 | P12: https://goo.gl/maps/tEHN4qjDe9CnFEJY9 | Q12: <iframe src="https://www.google.com/maps/embed?pb=!1m18!1m12!1m3!1d25515.702819714523!2d-3.3043866604492185!3d36.927105400000016!2m3!1f0!2f0!3f0!3m2!1i1024!2i768!4f13.1!3m3!1m2!1s0xd71c8740d75803f%3A0xdbcaad7920b6c8a!2sMinas%20de%20hierro%20del%20Cerro%20del%20Conjuro!5e0!3m2!1ses!2ses!4v1651829314169!5m2!1ses!2ses" width="600" height="450" style="border:0;" allowfullscreen="" loading="lazy" referrerpolicy="no-referrer-when-downgrade"></iframe> | R12: https://lh5.googleusercontent.com/p/AF1QipOD_SJndDbxAZgtgBMEiYlhZ5lWUmYCOFQTSnOw=w408-h306-k-no
A13: Mina La Probadora | B13: Mina | F13: 4M73+7W Güejar Sierra | G13: 18160 Güejar Sierra, Granada | H13: Güejar Sierra | I13: Granada | L13: - | M13: Sí | N13: 37.1132316 | O13: -3.3451627 | P13: https://goo.gl/maps/CJMTgtMPpDaHTmop7 | Q13: <iframe src="https://www.google.com/maps/embed?pb=!1m18!1m12!1m3!1d50906.54555845185!2d-3.3801816208984374!3d37.1132316!2m3!1f0!2f0!3f0!3m2!1i1024!2i768!4f13.1!3m3!1m2!1s0xd71dde9731e7eff%3A0x6a82b034604d3512!2sMina%20La%20Probadora!5e0!3m2!1ses!2ses!4v1651829358464!5m2!1ses!2ses" width="600" height="450" style="border:0;" allowfullscreen="" loading="lazy" referrerpolicy="no-referrer-when-downgrade"></iframe> | R13: https://lh5.googleusercontent.com/p/AF1QipPUSo75tCqIMOBFdQU0qj6YZ5pJYyO3kWfkXM-e=w408-h306-k-no
A14: Minas de la Cruz | B14: Mina | F14: 9572+H7 Las Juntas | G14: 18870, Granada | H14: Las Juntas | I14: Granada | L14: - | M14: Sí | N14: 37.3638884 | O14: -2.8492675 | P14: https://goo.gl/maps/xvmaNdeoVRqRru5k7 | Q14: <iframe src="https://www.google.com/maps/embed?pb=!1m18!1m12!1m3!1d50737.547421273535!2d-2.8842864208984373!3d37.363888400000015!2m3!1f0!2f0!3f0!3m2!1i1024!2i768!4f13.1!3m3!1m2!1s0xd6fdd5a9b0501b9%3A0x5d4e8974acaa2472!2sMinas%20de%20la%20Cruz!5e0!3m2!1ses!2ses!4v1651829431386!5m2!1ses!2ses" width="600" height="450" style="border:0;" allowfullscreen="" loading="lazy" referrerpolicy="no-referrer-when-downgrade"></iframe>
A15: LEGALIZACIÓN POZOS BELÉN DELGADO | B15: Ingeniero de minas | C15: 4,9 | D15: 49 | E15: viernes, Abierto 24 horas; sábado, Abierto 24 horas; domingo, Abierto 24 horas; lunes, Abierto 24 horas; martes, Abierto 24 horas; miércoles, Abierto 24 horas; jueves, Abierto 24 horas | F15: 68GR+MP Albolote | G15: C. Magallanes, Nº17, 18220 Albolote, Granada | H15: Albolote | I15: Granada | K15: 669 01 56 34 | L15: - | M15: No | N15: 37.2267479 | O15: -3.6582004 | P15: https://goo.gl/maps/VtyQaq3AN6JBM8fB8 | Q15: <iframe src="https://www.google.com/maps/embed?pb=!1m18!1m12!1m3!1d406641.0477509711!2d-3.9383517671874984!3d37.22674789999999!2m3!1f0!2f0!3f0!3m2!1i1024!2i768!4f13.1!3m3!1m2!1s0xd71fdedaebec3df%3A0x3d2366d21de23e2d!2sLEGALIZACI%C3%93N%20POZOS%20BEL%C3%89N%20DELGADO!5e0!3m2!1ses!2ses!4v1651829613434!5m2!1ses!2ses" width="600" height="450" style="border:0;" allowfullscreen="" loading="lazy" referrerpolicy="no-referrer-when-downgrade"></iframe> | R15: https://lh5.googleusercontent.com/p/AF1QipPbs1jmptDAumSjwO7R7VuNc4FBZXDMIOLXEIM0=w408-h306-k-no
A16: Mina Aguablanca | B16: Mina | C16: 3,0 | D16: 3 | F16: XR89+6V Monesterio | G16: Paraje Mina Aguablanca, s/n, 06260 Monesterio, Badajoz | H16: Monesterio | I16: Badajoz | K16: 924 58 80 00 | L16: - | M16: Sí | N16: 37.9656176 | O16: -6.1802168 | P16: https://goo.gl/maps/Ko3tmCiRgPD1LcGS9 | Q16: <iframe src="https://www.google.com/maps/embed?pb=!1m18!1m12!1m3!1d100655.82778324383!2d-6.250365041796875!3d37.96558480000001!2m3!1f0!2f0!3f0!3m2!1i1024!2i768!4f13.1!3m3!1m2!1s0xd13cf6cbee8f077%3A0xc54669c16605f5fa!2sMina%20Aguablanca!5e0!3m2!1ses!2ses!4v1651830066543!5m2!1ses!2ses" width="600" height="450" style="border:0;" allowfullscreen="" loading="lazy" referrerpolicy="no-referrer-when-downgrade"></iframe> | R16: https://streetviewpixels-pa.googleapis.com/v1/thumbnail?panoid=hWZ4YfjID6_qL7CbmmwRTA&cb_client=search.gws-prod.gps&w=408&h=240&yaw=231.42943&pitch=0&thumbfov=100
A17: Emilio del Rey Delgado | B17: Ingeniero de minas | E17: viernes, De 8:00 a 20:00; sábado, Cerrado; domingo, Cerrado; lunes, De 8:00 a 20:00; martes, De 8:00 a 20:00; miércoles, De 8:00 a 20:00; jueves, De 8:00 a 20:00 | F17: V6M9+VG Córdoba | G17: C. Conde de Gondomar, 13, 2º-8, 14003 Córdoba | H17: Córdoba | I17: Córdoba | K17: 677 87 36 54 | L17: - | M17: No | N17: 37.8846456 | O17: -4.7812327 | P17: https://goo.gl/maps/uq7Y3eXcMRAzJSam8 | Q17: <iframe src="https://www.google.com/maps/embed?pb=!1m18!1m12!1m3!1d50378.627910679126!2d-4.784485328307191!3d37.891534025745564!2m3!1f0!2f0!3f0!3m2!1i1024!2i768!4f13.1!3m3!1m2!1s0xd6cdf631d8460bb%3A0x188eb23a83fd3afe!2sEmilio%20del%20Rey%20Delgado!5e0!3m2!1ses!2ses!4v1651830143997!5m2!1ses!2ses" width="600" height="450" style="border:0;" allowfullscreen="" loading="lazy" referrerpolicy="no-referrer-when-downgrade"></iframe> | R17: https://streetviewpixels-pa.googleapis.com/v1/thumbnail?panoid=X70RSuaNRsnY3VfC2h6-ug&cb_client=search.gws-prod.gps&w=408&h=240&yaw=81.007355&pitch=0&thumbfov=100
A18: PGMA S.L.P. | B18: Ingeniero de minas | F18: V6Q9+8Q Córdoba | G18: Av. Ronda de los Tejares, 13, 14001 Córdoba | H18: Córdoba | I18: Córdoba | J18: pgma.es | K18: 957 48 00 01 | L18: info@pgma.es | M18: No | N18: 37.8882625 | O18: -4.78062 | P18: https://goo.gl/maps/W37jK7imBcNmnqrA9 | Q18: <iframe src="https://www.google.com/maps/embed?pb=!1m18!1m12!1m3!1d50378.627910679126!2d-4.784485328307191!3d37.891534025745564!2m3!1f0!2f0!3f0!3m2!1i1024!2i768!4f13.1!3m3!1m2!1s0xd6cdf64ea57a99f%3A0x21b1fe601bb175d3!2sPGMA%20S.L.P.!5e0!3m2!1ses!2ses!4v1651830161387!5m2!1ses!2ses" width="600" height="450" style="border:0;" allowfullscreen="" loading="lazy" referrerpolicy="no-referrer-when-downgrade"></iframe> | R18: https://streetviewpixels-pa.googleapis.com/v1/thumbnail?panoid=ZweIsjFUv8ECIuNGf1jV5A&cb_client=search.gws-prod.gps&w=408&h=240&yaw=146.02719&pitch=0&thumbfov=100
A19: Minas de Calamón | B19: Mina | C19: 5,0 | D19: 4 | F19: RWV3+VP Posadas | G19: 14730 Posadas, Córdoba | H19: Posadas | I19: Córdoba | L19: - | M19: Sí | N19: 37.8447222 | O19: -5.0956362 | P19: https://goo.gl/maps/Ur3TVJvUUJXrNCUm7 | Q19: <iframe src="https://www.google.com/maps/embed?pb=!1m18!1m12!1m3!1d50410.64380094292!2d-5.130655120898437!3d37.84472220000001!2m3!1f0!2f0!3f0!3m2!1i1024!2i768!4f13.1!3m3!1m2!1s0xd12d50c880cc5c3%3A0x932066eb9021d2bf!2sMinas%20de%20Calam%C3%B3n!5e0!3m2!1ses!2ses!4v1651830197247!5m2!1ses!2ses" width="600" height="450" style="border:0;" allowfullscreen="" loading="lazy" referrerpolicy="no-referrer-when-downgrade"></iframe> | R19: https://lh5.googleusercontent.com/p/AF1QipPBvOhQVV-7X3MHL3oqcmjLDAGvyQvWB4gzudbK=w408-h306-k-no
A20: Mario Antonio León Solís | B20: Ingeniero de minas | C20: 5,0 | D20: 1 | F20: V6VC+J4 Córdoba | G20: C. de los Plateros, 9, 14006 Córdoba | H20: Córdoba | I20: Córdoba | K20: 957 40 25 15 | L20: - | M20: Sí | N20: 37.8940679 | O20: -4.7797064 | P20: https://goo.gl/maps/4LjMQE2vp8iVu4VH7 | Q20: <iframe src="https://www.google.com/maps/embed?pb=!1m18!1m12!1m3!1d50378.627910679126!2d-4.784485328307217!3d37.891534025745564!2m3!1f0!2f0!3f0!3m2!1i1024!2i768!4f13.1!3m3!1m2!1s0xd6cdf6fdc3cd789%3A0xf9fd740f68c5fd8b!2sMario%20Antonio%20Le%C3%B3n%20Sol%C3%ADs!5e0!3m2!1ses!2ses!4v1651830214340!5m2!1ses!2ses" width="600" height="450" style="border:0;" allowfullscreen="" loading="lazy" referrerpolicy="no-referrer-when-downgrade"></iframe> | R20: https://streetviewpixels-pa.googleapis.com/v1/thumbnail?panoid=bmCHoTGtVsoiDfog24ySZw&cb_client=search.gws-prod.gps&w=408&h=240&yaw=265.68716&pitch=0&thumbfov=100
A21: pozosyproyectosmineros SERVICIOS DE PROYECTOS Y GESTIÓN MINERA | B21: Ingeniero de minas | C21: 5,0 | D21: 2 | E21: viernes, De 9:00 a 20:00; sábado, Cerrado; domingo, Cerrado; lunes, De 9:00 a 20:00; martes, De 9:00 a 20:00; miércoles, De 9:00 a 20:00; jueves, De 9:00 a 20:00 | F21: 8JFJ+M3 Rute | G21: C/ Cervantes s/n, casa nº 8 (Residencial Don Juan, 14960 Rute, Córdoba | H21: Rute | I21: Córdoba | J21: pozosyproyectosmineros.es | K21: 639 71 56 56 | L21: info@pozosyproyectosmineros.es | M21: No | N21: 37.3242278 | O21: -4.3698016 | P21: https://goo.gl/maps/JJtThvobQY7zQ44p9 | Q21: <iframe src="https://www.google.com/maps/embed?pb=!1m18!1m12!1m3!1d50764.35671722261!2d-4.404818020898437!3d37.324221099999995!2m3!1f0!2f0!3f0!3m2!1i1024!2i768!4f13.1!3m3!1m2!1s0xd6d82476aaaaaab%3A0x259f3dc0dafa17b2!2spozosyproyectosmineros%20SERVICIOS%20DE%20PROYECTOS%20Y%20GESTI%C3%93N%20MINERA!5e0!3m2!1ses!2ses!4v1651830266262!5m2!1ses!2ses" width="600" height="450" style="border:0;" allowfullscreen="" loading="lazy" referrerpolicy="no-referrer-when-downgrade"></iframe> | R21: https://streetviewpixels-pa.googleapis.com/v1/thumbnail?panoid=1mJEiGB5emr6BjQN1lGzdQ&cb_client=search.gws-prod.gps&w=408&h=240&yaw=289.07404&pitch=0&thumbfov=100
A22: Mina Diógenes | B22: Mina | C22: 4,8 | D22: 4 | F22: GV9M+Q7 Solana del Pino | G22: Cdad., 13593 Solana del Pino, Cdad. Real | H22: Solana del Pino | I22: Cdad. Real | L22: - | M22: Sí | N22: 38.5193885 | O22: -4.1167625 | P22: https://goo.gl/maps/DQgnu5WFvYa3PJCY6 | Q22: <iframe src="https://www.google.com/maps/embed?pb=!1m18!1m12!1m3!1d799135.2887361534!2d-4.677093234374993!3d38.51942280000001!2m3!1f0!2f0!3f0!3m2!1i1024!2i768!4f13.1!3m3!1m2!1s0xd6c745dc090dc9f%3A0xd81fe4765d6682bc!2sMina%20Di%C3%B3genes!5e0!3m2!1ses!2ses!4v1651830520621!5m2!1ses!2ses" width="600" height="450" style="border:0;" allowfullscreen="" loading="lazy" referrerpolicy="no-referrer-when-downgrade"></iframe> | R22: https://lh5.googleusercontent.com/p/AF1QipPr_5ABd9xPWZF1DHGmHdqE3uZghMi8BHwdDtFA=w408-h306-k-no
A23: Mina La Petaca | B23: Mina | C23: 4,0 | D23: 1 | F23: HQ32+C2 Ventillas | G23: Unnamed Road, 13591, Cdad. Real | H23: Ventillas | I23: Cdad. Real | L23: - | M23: Sí | N23: 38.5535495 | O23: -4.2499592 | P23: https://goo.gl/maps/a65Df4uPxLBLGudh7 | Q23: <iframe src="https://www.google.com/maps/embed?pb=!1m18!1m12!1m3!1d798756.2690521735!2d-4.810261934375004!3d38.553549499999995!2m3!1f0!2f0!3f0!3m2!1i1024!2i768!4f13.1!3m3!1m2!1s0xd6c799b71c55e21%3A0x666beda37c7954dd!2sMina%20La%20Petaca!5e0!3m2!1ses!2ses!4v1651830540293!5m2!1ses!2ses" width="600" height="450" style="border:0;" allowfullscreen="" loading="lazy" referrerpolicy="no-referrer-when-downgrade"></iframe> | R23: https://lh5.googleusercontent.com/p/AF1QipOLMuwETFKmG1QCmTFYNg0nNcXh_eCiAzmDrj8i=w408-h306-k-no
A24: Oxidos ferricos s.a. Mina las piletas | B24: Mina | E24: viernes, De 8:00 a 18:00; sábado, Cerrado; domingo, Cerrado; lunes, De 8:00 a 18:00; martes, De 8:00 a 18:00; miércoles, De 8:00 a 18:00; jueves, De 8:00 a 18:00 | F24: 63XF+R5 Rambla del Agua | G24: Cam. Nuevo del Gobernador, 18512 Huéneja, Granada | H24: Rambla del Agua | I24: Granada | L24: - | M24: Sí | N24: 37.2495701 | O24: -2.9270595 | P24: https://goo.gl/maps/v89K9RS66c68sdh87 | Q24: <iframe src="https://www.google.com/maps/embed?pb=!1m18!1m12!1m3!1d101629.48777304254!2d-2.997097341796875!3d37.2495701!2m3!1f0!2f0!3f0!3m2!1i1024!2i768!4f13.1!3m3!1m2!1s0xd7027eff1bbc4c5%3A0xfc21f7b7c1b1bcd1!2sOxidos%20ferricos%20s.a.%20Mina%20las%20piletas!5e0!3m2!1ses!2ses!4v1651830864694!5m2!1ses!2ses" width="600" height="450" style="border:0;" allowfullscreen="" loading="lazy" referrerpolicy="no-referrer-when-downgrade"></iframe> | R24: https://streetviewpixels-pa.googleapis.com/v1/thumbnail?panoid=NRalodNjPRfmkXjMtzS65g&cb_client=search.gws-prod.gps&w=408&h=240&yaw=278.11935&pitch=0&thumbfov=100
A25: Argudo &amp; Castillo Ingeniería | B25: Ingeniero de minas | C25: 5,0 | D25: 1 | E25: viernes, De 8:30 a 14:00; sábado, Cerrado; domingo, Cerrado; lunes, De 8:30 a 19:00; martes, De 8:30 a 19:00; miércoles, De 8:30 a 19:00; jueves, De 8:30 a 19:00 | F25: Q699+QM Jaén | G25: Av. Granada, 57, 23003 Jaén | H25: Jaén | I25: Jaén | J25: argudoycastillo.com | K25: 953 00 00 22 | L25: - | M25: No | N25: 37.7694977 | O25: -3.7808412 | P25: https://goo.gl/maps/zduyq87yUevr4r8w8 | Q25: <iframe src="https://www.google.com/maps/embed?pb=!1m18!1m12!1m3!1d100924.06273402969!2d-3.850880241796875!3d37.7694831!2m3!1f0!2f0!3f0!3m2!1i1024!2i768!4f13.1!3m3!1m2!1s0xd6dd79f62edb121%3A0xe2932fc5f5cdf55a!2sArgudo%20%26%20Castillo%20Ingenier%C3%ADa!5e0!3m2!1ses!2ses!4v1651830978012!5m2!1ses!2ses" width="600" height="450" style="border:0;" allowfullscreen="" loading="lazy" referrerpolicy="no-referrer-when-downgrade"></iframe> | R25: https://lh5.googleusercontent.com/p/AF1QipP5k1VtnsbRa62tFI47xE3OE2-P9MXJy_8yCao_=w408-h272-k-no
A26: Pozo de San Vicente | B26: Mina | C26: 4,5 | D26: 15 | E26: viernes, Abierto 24 horas; sábado, Abierto 24 horas; domingo, Abierto 24 horas; lunes, Abierto 24 horas; martes, Abierto 24 horas; miércoles, Abierto 24 horas; jueves, Abierto 24 horas | F26: 49HH+W6 Linares | G26: 23700 Linares, Jaén | H26: Linares | I26: Jaén | J26: redjaen.es | L26: - | M26: Sí | N26: 38.1298638 | O26: -3.6219149 | P26: https://goo.gl/maps/5ep373h7VjTg4hg57 | Q26: <iframe src="https://www.google.com/maps/embed?pb=!1m18!1m12!1m3!1d200860.42661567146!2d-3.7619905835937204!3d38.129863799999995!2m3!1f0!2f0!3f0!3m2!1i1024!2i768!4f13.1!3m3!1m2!1s0xd6e9b01e2f8dcbd%3A0x486dab6a2c0bc4de!2sPozo%20de%20San%20Vicente!5e0!3m2!1ses!2ses!4v1651831281450!5m2!1ses!2ses" width="600" height="450" style="border:0;" allowfullscreen="" loading="lazy" referrerpolicy="no-referrer-when-downgrade"></iframe> | R26: https://lh5.googleusercontent.com/p/AF1QipMj2xnIksuo4ToqQzrblIj1E_RRSzxKPHyAU-pu=w426-h240-k-no
A27: Pozo San Jose | B27: Mina | F27: 49RF+HQ Linares | G27: 23700 Linares, Jaén | H27: Linares | I27: Jaén | L27: - | M27: Sí | N27: 38.1414785 | O27: -3.6255265 | P27: https://goo.gl/maps/d8GLambLnXHLPK7u7 | Q27: <iframe src="https://www.google.com/maps/embed?pb=!1m18!1m12!1m3!1d200828.46170584048!2d-3.7656021835937112!3d38.141478500000005!2m3!1f0!2f0!3f0!3m2!1i1024!2i768!4f13.1!3m3!1m2!1s0xd6e9b8504ab4f21%3A0xdc916e912398d68f!2sPozo%20San%20Jose!5e0!3m2!1ses!2ses!4v1651831290012!5m2!1ses!2ses" width="600" height="450" style="border:0;" allowfullscreen="" loading="lazy" referrerpolicy="no-referrer-when-downgrade"></iframe> | R27: https://lh5.googleusercontent.com/p/AF1QipOl041eZR2zxFcaN_OuWquiYCe_QDHj7NzpS15G=w426-h240-k-no
A28: Pozo La Union | B28: Mina | F28: 49Q7+73 Linares | G28: 23700 Linares, Jaén | H28: Linares | I28: Jaén | L28: - | M28: Sí | N28: 38.1381702 | O28: -3.637355 | P28: https://goo.gl/maps/7DwFNTztXsTmy4Dj7 | Q28: <iframe src="https://www.google.com/maps/embed?pb=!1m18!1m12!1m3!1d200837.56734564947!2d-3.7774306835937526!3d38.138170200000005!2m3!1f0!2f0!3f0!3m2!1i1024!2i768!4f13.1!3m3!1m2!1s0xd6e9ba67ae6e1a3%3A0x367d4778e677ef22!2sPozo%20La%20Union!5e0!3m2!1ses!2ses!4v1651831312121!5m2!1ses!2ses" width="600" height="450" style="border:0;" allowfullscreen="" loading="lazy" referrerpolicy="no-referrer-when-downgrade"></iframe> | R28: https://streetviewpixels-pa.googleapis.com/v1/thumbnail?panoid=WdZ0UmcjtLZJbvaGf0XsKQ&cb_client=search.gws-prod.gps&w=408&h=240&yaw=282.62646&pitch=0&thumbfov=100
